Workbook

Sheet Read Me
B1: Chapter 10: Tangible Non-current Assets and Depreciation
B2: Senior 1 Accounting. Free to use and share. Not for sale.
B4: How to use this workbook
B5: 1. Read the notes first. Then open the orange Worked tabs: change any blue figure and watch the answers update.
B6: 2. Try the blue question tabs in order, Level 1 to Level 5. Type your answers in the yellow cells.
B7: 3. The small column next to each yellow cell shows ✓ (correct) or ✗ (try again). Your score is at the top of each question.
B8: 4. Particulars and dates are given so the sheet can mark your figures. Try writing each account or statement on paper first.
B9: 5. Written answers cannot be marked by Excel. Compare them with the model answers on the green tabs.
B10: 6. The green Ans tabs show the full solutions in exam format.
B12: Colour key
B13: 1000 | H13: Blue figure: data from the question. Teachers may change it to make a new version.
B14: 1000 | H14: Black figure: a formula. Do not type over it.
H15: Yellow cell: type your answer here (numbers only; enter 0 for nil).
B16: 1000 | H16: Green cell: the correct answer (Ans tabs).
B18: Formats used
B19: Journal: Date | Particulars | Debit (RM) | Credit (RM).
B20: Ledger account: Dr side and Cr side, each with Date | Particulars | Folio | Amount (RM). Folio: GJ = general journal, CB = cash book.
B21: Statement of Profit or Loss: marker (Add / Less) | Particulars | RM | RM | RM.
B22: Statement of Financial Position: the same, with Cost | Accumulated Depreciation | Carrying Amount under the RM headings.
B24: Sheets in this workbook
B25: Sheet | I25: What it is
B26: Straight Line | I26: Worked example (orange tab)
B27: Reducing Balance | I27: Worked example (orange tab)
B28: Other Methods | I28: Worked example (orange tab)
B29: Disposal | I29: Worked example (orange tab)
B30: Q10.9 | I30: Structured question, Level 1: Easy (blue tab). Answers: Q10.9 Ans (green tab).
B31: Q10.10 | I31: Structured question, Level 2: Easy to medium (blue tab). Answers: Q10.10 Ans (green tab).
B32: Q10.11 | I32: Structured question, Level 3: Medium (blue tab). Answers: Q10.11 Ans (green tab).
B33: Q10.12 | I33: Structured question, Level 4: Hard (blue tab). Answers: Q10.12 Ans (green tab).
B34: Q10.13 | I34: Structured question, Level 5: Challenge (blue tab). Answers: Q10.13 Ans (green tab).

Sheet Straight Line
B1: Straight Line
B2: Worked example. Change any blue figure and every answer below updates.
B3: Black figures are formulas. Do not type over them.
B5: Worked examples 10.1 and 10.4: straight line method. Annual depreciation = (Cost - Residual value) / Useful life.
B6: Inputs | X6: Figure
B7: Cost of machine (RM) | X7: 20000
B8: Residual value (RM) | X8: 2000
B9: Useful life (years, up to 8) | X9: 4
B11: Annual depreciation (RM) | X11: =($X$7-$X$8)/$X$9 -> 4500
B13: Year | I13: Depreciation for year (RM) | Q13: Accumulated depreciation (RM) | Y13: Carrying amount at end (RM)
B14: 1 | I14: =IF(1>$X$9,"",$X$11) -> 4500 | Q14: =IF(1>$X$9,"",$I$14) -> 4500 | Y14: =IF(1>$X$9,"",$X$7-$Q$14) -> 15500
B15: 2 | I15: =IF(2>$X$9,"",$X$11) -> 4500 | Q15: =IF(2>$X$9,"",$Q$14+$I$15) -> 9000 | Y15: =IF(2>$X$9,"",$X$7-$Q$15) -> 11000
B16: 3 | I16: =IF(3>$X$9,"",$X$11) -> 4500 | Q16: =IF(3>$X$9,"",$Q$15+$I$16) -> 13500 | Y16: =IF(3>$X$9,"",$X$7-$Q$16) -> 6500
B17: 4 | I17: =IF(4>$X$9,"",$X$11) -> 4500 | Q17: =IF(4>$X$9,"",$Q$16+$I$17) -> 18000 | Y17: =IF(4>$X$9,"",$X$7-$Q$17) -> 2000
B18: 5 | I18: =IF(5>$X$9,"",$X$11) | Q18: =IF(5>$X$9,"",$Q$17+$I$18) | Y18: =IF(5>$X$9,"",$X$7-$Q$18)
B19: 6 | I19: =IF(6>$X$9,"",$X$11) | Q19: =IF(6>$X$9,"",$Q$18+$I$19) | Y19: =IF(6>$X$9,"",$X$7-$Q$19)
B20: 7 | I20: =IF(7>$X$9,"",$X$11) | Q20: =IF(7>$X$9,"",$Q$19+$I$20) | Y20: =IF(7>$X$9,"",$X$7-$Q$20)
B21: 8 | I21: =IF(8>$X$9,"",$X$11) | Q21: =IF(8>$X$9,"",$Q$20+$I$21) | Y21: =IF(8>$X$9,"",$X$7-$Q$21)
B22: The charge is the SAME every year. Rows after the last year of useful life stay blank.
B24: Example 10.4: the ledger accounts for the first two years
B25: Dr | E25: Machinery Account | AD25: Cr
B26: Date | E26: Particulars | L26: Folio | M26: Amount (RM) | R26: Date | U26: Particulars | AB26: Folio | AC26: Amount (RM)
B27: Year 1 Jan 1 | E27: Bank | L27: CB1 | M27: =$X$7 -> 20000 | R27: Year 1 Dec 31 | U27: Balance c/d | AC27: =$X$7 -> 20000
M28: =SUM(M27:M27) -> 20000 | AC28: =SUM(AC27:AC27) -> 20000
B29: Year 2 Jan 1 | E29: Balance b/d | M29: =$X$7 -> 20000
B31: Dr | E31: Provision for Depreciation of Machinery Account | AD31: Cr
B32: Date | E32: Particulars | L32: Folio | M32: Amount (RM) | R32: Date | U32: Particulars | AB32: Folio | AC32: Amount (RM)
B33: Year 1 Dec 31 | E33: Balance c/d | M33: =$X$11 -> 4500 | R33: Year 1 Dec 31 | U33: Income statement | AB33: GJ1 | AC33: =$X$11 -> 4500
M34: =SUM(M33:M33) -> 4500 | AC34: =SUM(AC33:AC33) -> 4500
B35: Year 2 Dec 31 | E35: Balance c/d | M35: =2*$X$11 -> 9000 | R35: Year 2 Jan 1 | U35: Balance b/d | AC35: =$X$11 -> 4500
R36: Year 2 Dec 31 | U36: Income statement | AB36: GJ2 | AC36: =$X$11 -> 4500
M37: =SUM(M35:M36) -> 9000 | AC37: =SUM(AC35:AC36) -> 9000
R38: Year 3 Jan 1 | U38: Balance b/d | AC38: =2*$X$11 -> 9000
B40: Statement of Financial Position (extract) at the end of Year 2
E41: Particulars | R41: RM | W41: RM | AB41: RM
R42: Cost | W42: Accumulated Depreciation | AB42: Carrying Amount
E43: Non-current assets
E44: Machinery | R44: =$X$7 -> 20000 | W44: =2*$X$11 -> 9000 | AB44: =$X$7-2*$X$11 -> 11000

Sheet Reducing Balance
B1: Reducing Balance
B2: Worked example. Change any blue figure and every answer below updates.
B3: Black figures are formulas. Do not type over them.
B5: Worked example 10.2: reducing balance method. Depreciation = carrying amount at start of year x rate.
B6: Inputs | X6: Figure
B7: Cost of equipment (RM) | X7: 10000
B8: Depreciation rate | X8: 0.2
B10: Year | E10: Carrying amount at start (RM) | L10: Depreciation (RM) | S10: Accumulated depreciation (RM) | Z10: Carrying amount at end (RM)
B11: 1 | E11: =$X$7 -> 10000 | L11: =ROUND($E$11*$X$8,2) -> 2000 | S11: =$L$11 -> 2000 | Z11: =$E$11-$L$11 -> 8000
B12: 2 | E12: =$Z$11 -> 8000 | L12: =ROUND($E$12*$X$8,2) -> 1600 | S12: =$S$11+$L$12 -> 3600 | Z12: =$E$12-$L$12 -> 6400
B13: 3 | E13: =$Z$12 -> 6400 | L13: =ROUND($E$13*$X$8,2) -> 1280 | S13: =$S$12+$L$13 -> 4880 | Z13: =$E$13-$L$13 -> 5120
B14: 4 | E14: =$Z$13 -> 5120 | L14: =ROUND($E$14*$X$8,2) -> 1024 | S14: =$S$13+$L$14 -> 5904 | Z14: =$E$14-$L$14 -> 4096
B15: The charge FALLS every year because the carrying amount falls. Common mistake: using cost after Year 1.

Sheet Other Methods
B1: Other Methods
B2: Worked example. Change any blue figure and every answer below updates.
B3: Black figures are formulas. Do not type over them.
B5: Straight line vs reducing balance on the same asset, the revaluation method and part-year depreciation.
B6: Compare methods: inputs | X6: Figure
B7: Cost of asset (RM) | X7: 16000
B8: Rate per year | X8: 0.25
B10: Year | E10: Straight line depreciation (RM) | L10: Straight line carrying amount (RM) | S10: Reducing balance depreciation (RM) | Z10: Reducing balance carrying amount (RM)
B11: 1 | E11: =$X$7*$X$8 -> 4000 | L11: =$X$7-1*$X$7*$X$8 -> 12000 | S11: =ROUND(($X$7)*$X$8,2) -> 4000 | Z11: =$X$7-$S$11 -> 12000
B12: 2 | E12: =$X$7*$X$8 -> 4000 | L12: =$X$7-2*$X$7*$X$8 -> 8000 | S12: =ROUND(($X$7-$S$11)*$X$8,2) -> 3000 | Z12: =$X$7-$S$11-$S$12 -> 9000
B13: 3 | E13: =$X$7*$X$8 -> 4000 | L13: =$X$7-3*$X$7*$X$8 -> 4000 | S13: =ROUND(($X$7-$S$11-$S$12)*$X$8,2) -> 2250 | Z13: =$X$7-$S$11-$S$12-$S$13 -> 6750
B14: 4 | E14: =$X$7*$X$8 -> 4000 | L14: =$X$7-4*$X$7*$X$8 -> 0 | S14: =ROUND(($X$7-$S$11-$S$12-$S$13)*$X$8,2) -> 1687.5 | Z14: =$X$7-$S$11-$S$12-$S$13-$S$14 -> 5062.5
B15: Straight line applies the rate to COST. Reducing balance applies the rate to the carrying amount.
B17: Worked example 10.3: revaluation method (loose tools)
B18: Inputs | X18: Figure
B19: Loose tools at start of year (RM) | X19: 1200
B20: Tools bought during the year (RM) | X20: 500
B21: Loose tools valued at end of year (RM) | X21: 1100
B23: Depreciation = opening + purchases - closing (RM) | X23: =$X$19+$X$20-$X$21 -> 600
B25: Section 9: asset bought part way through the year (monthly basis)
B26: Inputs | X26: Figure
B27: Cost of machine (RM) | X27: 12000
B28: Rate per year on cost | X28: 0.1
B29: Months owned in the first year | X29: 9
B31: Full year depreciation (RM) | X31: =$X$27*$X$28 -> 1200
B32: Depreciation for the months owned (RM) | X32: =$X$27*$X$28*$X$29/12 -> 900

Sheet Disposal
B1: Disposal
B2: Worked example. Change any blue figure and every answer below updates.
B3: Black figures are formulas. Do not type over them.
B5: Worked example 10.5: disposal of a van. Profit or loss on disposal = sale proceeds - carrying amount.
B6: Inputs | X6: Figure
B7: Cost of van (RM) | X7: 30000
B8: Accumulated depreciation to date of sale (RM) | X8: 18000
B9: Sale proceeds (RM) | X9: 10000
B11: Carrying amount at date of sale (RM) | X11: =$X$7-$X$8 -> 12000
B12: Profit (+) or loss (-) on disposal (RM) | X12: =$X$9-$X$11 -> -2000
B13: Treatment | X13: =IF($X$12>0,"Profit: other income in the SPL",IF($X$12<0,"Loss: expense in the SPL","No profit or loss")) -> Loss: expense in the SPL
B15: Dr | E15: Disposal of Van Account | AD15: Cr
B16: Date | E16: Particulars | L16: Folio | M16: Amount (RM) | R16: Date | U16: Particulars | AB16: Folio | AC16: Amount (RM)
B17: Date of sale | E17: Van (cost) | L17: GJ1 | M17: =$X$7 -> 30000 | R17: Date of sale | U17: Provision for depreciation | AB17: GJ1 | AC17: =$X$8 -> 18000
B18: Year end | E18: Income statement (profit on disposal) | L18: GJ2 | M18: =MAX($X$12,0) -> 0 | R18: Date of sale | U18: Bank | AB18: CB1 | AC18: =$X$9 -> 10000
R19: Year end | U19: Income statement (loss on disposal) | AB19: GJ2 | AC19: =MAX(-$X$12,0) -> 2000
M20: =SUM(M17:M19) -> 30000 | AC20: =SUM(AC17:AC19) -> 30000
B21: A dash means no amount. A profit balances the account on the debit side; a loss on the credit side.

Sheet Q10.9
B1: Question 10.9 (Level 1: Easy)
B2: Type your answers in the yellow cells. Numbers only: no RM, no commas. Enter 0 where the answer is nil. ✓ = correct, ✗ = try again.
B3: Your score: | H3: =COUNTIF(B4:AG29,"✓")&" correct out of 11 answer cells" -> 0 correct out of 11 answer cells
B5: On 1 January 2024 a business bought a delivery van for RM18,000. It expects to use the van for 5 years and then sell it for RM3,000. The straight line method is used. The year end is 31 December.
B6: Figures from the question | X6: Figure
B7: Cost of van (RM) | X7: 18000
B8: Residual value (RM) | X8: 3000
B9: Useful life (years) | X9: 5
B12: a) Calculate the annual depreciation. (2)
B13: Annual depreciation (RM) | AC13: =IF(X13="","",IFERROR(IF(ABS(ABS(X13)-ABS('Q10.9 Ans'!X13))<0.5,"✓","✗"),"✗"))
B15: b) Complete the table. (4)
B16: Year | I16: Depreciation (RM) | Q16: Accumulated depreciation (RM) | Y16: Carrying amount at end of year (RM)
B17: 2024 | P17: =IF(I17="","",IFERROR(IF(ABS(ABS(I17)-ABS('Q10.9 Ans'!I17))<0.5,"✓","✗"),"✗")) | X17: =IF(Q17="","",IFERROR(IF(ABS(ABS(Q17)-ABS('Q10.9 Ans'!Q17))<0.5,"✓","✗"),"✗")) | AF17: =IF(Y17="","",IFERROR(IF(ABS(ABS(Y17)-ABS('Q10.9 Ans'!Y17))<0.5,"✓","✗"),"✗"))
B18: 2025 | P18: =IF(I18="","",IFERROR(IF(ABS(ABS(I18)-ABS('Q10.9 Ans'!I18))<0.5,"✓","✗"),"✗")) | X18: =IF(Q18="","",IFERROR(IF(ABS(ABS(Q18)-ABS('Q10.9 Ans'!Q18))<0.5,"✓","✗"),"✗")) | AF18: =IF(Y18="","",IFERROR(IF(ABS(ABS(Y18)-ABS('Q10.9 Ans'!Y18))<0.5,"✓","✗"),"✗"))
B20: c) Show the Statement of Financial Position extract for the van at 31 December 2025. (2)
B21: Statement of Financial Position (extract) at 31 December 2025
E22: Particulars | R22: RM | W22: RM | AB22: RM
R23: Cost | W23: Accumulated Depreciation | AB23: Carrying Amount
E24: Non-current assets
E25: Delivery van | V25: =IF(R25="","",IFERROR(IF(ABS(ABS(R25)-ABS('Q10.9 Ans'!R25))<0.5,"✓","✗"),"✗")) | AA25: =IF(W25="","",IFERROR(IF(ABS(ABS(W25)-ABS('Q10.9 Ans'!W25))<0.5,"✓","✗"),"✗")) | AF25: =IF(AB25="","",IFERROR(IF(ABS(ABS(AB25)-ABS('Q10.9 Ans'!AB25))<0.5,"✓","✗"),"✗"))
B27: d) State one cause of depreciation for a delivery van. (1)
B28: Cause of depreciation | AC28: =IF(T28="","",IF(OR(LOWER(TRIM(T28))="wear and tear",LOWER(TRIM(T28))="passage of time",LOWER(TRIM(T28))="obsolescence"),"✓","✗"))

Sheet Q10.10
B1: Question 10.10 (Level 2: Easy to medium)
B2: Type your answers in the yellow cells. Numbers only: no RM, no commas. Enter 0 where the answer is nil. ✓ = correct, ✗ = try again.
B3: Your score: | H3: =COUNTIF(B4:AG27,"✓")&" correct out of 8 answer cells" -> 0 correct out of 8 answer cells
B5: A business bought a new machine. It paid the amounts below.
B6: Figures from the question | X6: Figure
B7: Purchase price of machine (RM) | X7: 22000
B8: Delivery to the factory (RM) | X8: 600
B9: Installation (RM) | X9: 900
B10: Insurance for the first year (RM) | X10: 400
B11: Repair after six months of use (RM) | X11: 250
B14: a) Calculate the cost of the machine to be shown as a non-current asset. (2)
B15: Cost of the machine (RM) | AC15: =IF(X15="","",IFERROR(IF(ABS(ABS(X15)-ABS('Q10.10 Ans'!X15))<0.5,"✓","✗"),"✗"))
B17: b) Classify each item as capital expenditure or revenue expenditure. (5)
B18: Purchase price | AC18: =IF(T18="","",IF(LOWER(TRIM(T18))=LOWER('Q10.10 Ans'!T18),"✓","✗"))
B19: Delivery | AC19: =IF(T19="","",IF(LOWER(TRIM(T19))=LOWER('Q10.10 Ans'!T19),"✓","✗"))
B20: Installation | AC20: =IF(T20="","",IF(LOWER(TRIM(T20))=LOWER('Q10.10 Ans'!T20),"✓","✗"))
B21: Insurance for the first year | AC21: =IF(T21="","",IF(LOWER(TRIM(T21))=LOWER('Q10.10 Ans'!T21),"✓","✗"))
B22: Repair after six months | AC22: =IF(T22="","",IF(LOWER(TRIM(T22))=LOWER('Q10.10 Ans'!T22),"✓","✗"))
B24: c) The installation cost was recorded as an expense by mistake. State the effect on profit for the year and on non-current assets. Ignore depreciation. (2)
B25: Profit for the year is understated by (RM) | AC25: =IF(X25="","",IFERROR(IF(ABS(ABS(X25)-ABS('Q10.10 Ans'!X25))<0.5,"✓","✗"),"✗"))
B26: Non-current assets are understated by (RM) | AC26: =IF(X26="","",IFERROR(IF(ABS(ABS(X26)-ABS('Q10.10 Ans'!X26))<0.5,"✓","✗"),"✗"))

Sheet Q10.11
B1: Question 10.11 (Level 3: Medium)
B2: Type your answers in the yellow cells. Numbers only: no RM, no commas. Enter 0 where the answer is nil. ✓ = correct, ✗ = try again.
B3: Your score: | H3: =COUNTIF(B4:AG37,"✓")&" correct out of 6 answer cells" -> 0 correct out of 6 answer cells
B5: The year end is 31 December.
C6: • A machine was bought on 1 April 2025 for RM12,000. Depreciation is 10% per year on cost, straight line, calculated on a monthly basis.
C7: • Loose tools were valued at RM2,000 on 1 January 2025. Tools costing RM800 were bought during 2025. On 31 December 2025 the loose tools were valued at RM2,100.
B8: Figures from the question | X8: Figure
B9: Cost of machine (RM) | X9: 12000
B10: Depreciation rate per year | X10: 0.1
B11: Months owned in 2025 | X11: 9
B12: Loose tools at 1 January 2025 (RM) | X12: 2000
B13: Loose tools bought in 2025 (RM) | X13: 800
B14: Loose tools at 31 December 2025 (RM) | X14: 2100
B17: a) Calculate depreciation on the machine for 2025 and for 2026. (3)
B18: Depreciation for 2025 (RM) | AC18: =IF(X18="","",IFERROR(IF(ABS(ABS(X18)-ABS('Q10.11 Ans'!X18))<0.5,"✓","✗"),"✗"))
B19: Depreciation for 2026 (RM) | AC19: =IF(X19="","",IFERROR(IF(ABS(ABS(X19)-ABS('Q10.11 Ans'!X19))<0.5,"✓","✗"),"✗"))
B21: b) Calculate the carrying amount of the machine at 31 December 2026. (1)
B22: Carrying amount at 31 December 2026 (RM) | AC22: =IF(X22="","",IFERROR(IF(ABS(ABS(X22)-ABS('Q10.11 Ans'!X22))<0.5,"✓","✗"),"✗"))
B24: c) Prepare the journal entry to record the machine depreciation for 2025. (2)
B25: Date | E25: Particulars | U25: Debit (RM) | AA25: Credit (RM)
B26: 2025 Dec 31 | E26: Income statement (depreciation) | Z26: =IF(U26="","",IFERROR(IF(ABS(ABS(U26)-ABS('Q10.11 Ans'!U26))<0.5,"✓","✗"),"✗"))
E27: Provision for depreciation of machinery | AF27: =IF(AA27="","",IFERROR(IF(ABS(ABS(AA27)-ABS('Q10.11 Ans'!AA27))<0.5,"✓","✗"),"✗"))
E28: (Being depreciation for 9 months at 10% per year on cost)
B30: d) Calculate the depreciation of loose tools for 2025. (2)
B31: Depreciation of loose tools (RM) | AC31: =IF(X31="","",IFERROR(IF(ABS(ABS(X31)-ABS('Q10.11 Ans'!X31))<0.5,"✓","✗"),"✗"))
B33: e) Explain why the revaluation method is used for loose tools. (2)

Sheet Q10.12
B1: Question 10.12 (Level 4: Hard)
B2: Type your answers in the yellow cells. Numbers only: no RM, no commas. Enter 0 where the answer is nil. ✓ = correct, ✗ = try again.
B3: Your score: | H3: =COUNTIF(B4:AG31,"✓")&" correct out of 20 answer cells" -> 0 correct out of 20 answer cells
B5: On 1 January 2023 Musa bought a machine for RM40,000. It is depreciated at 25% per year, reducing balance. The year end is 31 December. On 1 January 2026 the machine was sold for RM15,000 by cheque.
B6: Figures from the question | X6: Figure
B7: Cost of machine (RM) | X7: 40000
B8: Reducing balance rate | X8: 0.25
B9: Sale proceeds on 1 January 2026 (RM) | X9: 15000
B12: a) Calculate the depreciation for 2023, 2024 and 2025. (3)
B13: Year | E13: Carrying amount at start (RM) | L13: Depreciation (RM) | S13: Accumulated depreciation (RM) | Z13: Carrying amount at end (RM)
B14: 2023 | K14: =IF(E14="","",IFERROR(IF(ABS(ABS(E14)-ABS('Q10.12 Ans'!E14))<0.5,"✓","✗"),"✗")) | R14: =IF(L14="","",IFERROR(IF(ABS(ABS(L14)-ABS('Q10.12 Ans'!L14))<0.5,"✓","✗"),"✗")) | Y14: =IF(S14="","",IFERROR(IF(ABS(ABS(S14)-ABS('Q10.12 Ans'!S14))<0.5,"✓","✗"),"✗")) | AF14: =IF(Z14="","",IFERROR(IF(ABS(ABS(Z14)-ABS('Q10.12 Ans'!Z14))<0.5,"✓","✗"),"✗"))
B15: 2024 | K15: =IF(E15="","",IFERROR(IF(ABS(ABS(E15)-ABS('Q10.12 Ans'!E15))<0.5,"✓","✗"),"✗")) | R15: =IF(L15="","",IFERROR(IF(ABS(ABS(L15)-ABS('Q10.12 Ans'!L15))<0.5,"✓","✗"),"✗")) | Y15: =IF(S15="","",IFERROR(IF(ABS(ABS(S15)-ABS('Q10.12 Ans'!S15))<0.5,"✓","✗"),"✗")) | AF15: =IF(Z15="","",IFERROR(IF(ABS(ABS(Z15)-ABS('Q10.12 Ans'!Z15))<0.5,"✓","✗"),"✗"))
B16: 2025 | K16: =IF(E16="","",IFERROR(IF(ABS(ABS(E16)-ABS('Q10.12 Ans'!E16))<0.5,"✓","✗"),"✗")) | R16: =IF(L16="","",IFERROR(IF(ABS(ABS(L16)-ABS('Q10.12 Ans'!L16))<0.5,"✓","✗"),"✗")) | Y16: =IF(S16="","",IFERROR(IF(ABS(ABS(S16)-ABS('Q10.12 Ans'!S16))<0.5,"✓","✗"),"✗")) | AF16: =IF(Z16="","",IFERROR(IF(ABS(ABS(Z16)-ABS('Q10.12 Ans'!Z16))<0.5,"✓","✗"),"✗"))
B18: b) Show the carrying amount of the machine at 31 December 2025. (1)
B19: Carrying amount at 31 December 2025 (RM) | AC19: =IF(X19="","",IFERROR(IF(ABS(ABS(X19)-ABS('Q10.12 Ans'!X19))<0.5,"✓","✗"),"✗"))
B21: c) Prepare the Machinery disposal account. (5)
B22: Dr | E22: Machinery Disposal Account | AD22: Cr
B23: Date | E23: Particulars | L23: Folio | M23: Amount (RM) | R23: Date | U23: Particulars | AB23: Folio | AC23: Amount (RM)
B24: 2026 Jan 1 | E24: Machinery | L24: GJ1 | P24: =IF(M24="","",IFERROR(IF(ABS(ABS(M24)-ABS('Q10.12 Ans'!M24))<0.5,"✓","✗"),"✗")) | R24: 2026 Jan 1 | U24: Provision for depreciation | AB24: GJ1 | AF24: =IF(AC24="","",IFERROR(IF(ABS(ABS(AC24)-ABS('Q10.12 Ans'!AC24))<0.5,"✓","✗"),"✗"))
R25: Jan 1 | U25: Bank | AB25: CB1 | AF25: =IF(AC25="","",IFERROR(IF(ABS(ABS(AC25)-ABS('Q10.12 Ans'!AC25))<0.5,"✓","✗"),"✗"))
R26: Dec 31 | U26: Income statement (loss on disposal) | AB26: GJ2 | AF26: =IF(AC26="","",IFERROR(IF(ABS(ABS(AC26)-ABS('Q10.12 Ans'!AC26))<0.5,"✓","✗"),"✗"))
P27: =IF(M27="","",IFERROR(IF(ABS(ABS(M27)-ABS('Q10.12 Ans'!M27))<0.5,"✓","✗"),"✗")) | AF27: =IF(AC27="","",IFERROR(IF(ABS(ABS(AC27)-ABS('Q10.12 Ans'!AC27))<0.5,"✓","✗"),"✗"))
B29: d) State where the result of the disposal appears in the financial statements. (1)
B30: The loss on disposal is shown as | AC30: =IF(T30="","",IF(LOWER(TRIM(T30))=LOWER('Q10.12 Ans'!T30),"✓","✗"))

Sheet Q10.13
B1: Question 10.13 (Level 5: Challenge)
B2: Type your answers in the yellow cells. Numbers only: no RM, no commas. Enter 0 where the answer is nil. ✓ = correct, ✗ = try again.
B3: Your score: | H3: =COUNTIF(B4:AG55,"✓")&" correct out of 29 answer cells" -> 0 correct out of 29 answer cells
B5: Kwame's year ends on 31 December. He depreciates vans at 20% per year on cost, straight line. A full year's depreciation is charged in the year of purchase and none in the year of sale.
C6: • 1 January 2023: bought Van A for RM25,000.
C7: • 1 July 2024: bought Van B for RM30,000.
C8: • 1 October 2025: sold Van A for RM12,000, paid by cheque.
B9: Figures from the question | X9: Figure
B10: Cost of Van A (RM) | X10: 25000
B11: Cost of Van B (RM) | X11: 30000
B12: Depreciation rate on cost | X12: 0.2
B13: Sale proceeds of Van A (RM) | X13: 12000
B16: a) Calculate the depreciation charge for 2023, 2024 and 2025. (3)
B17: Depreciation for 2023 (RM) | AC17: =IF(X17="","",IFERROR(IF(ABS(ABS(X17)-ABS('Q10.13 Ans'!X17))<0.5,"✓","✗"),"✗"))
B18: Depreciation for 2024 (RM) | AC18: =IF(X18="","",IFERROR(IF(ABS(ABS(X18)-ABS('Q10.13 Ans'!X18))<0.5,"✓","✗"),"✗"))
B19: Depreciation for 2025 (RM) | AC19: =IF(X19="","",IFERROR(IF(ABS(ABS(X19)-ABS('Q10.13 Ans'!X19))<0.5,"✓","✗"),"✗"))
B21: b) Prepare the Provision for depreciation of vans account for 2023, 2024 and 2025. (6)
B22: Dr | E22: Provision for Depreciation of Vans Account | AD22: Cr
B23: Date | E23: Particulars | L23: Folio | M23: Amount (RM) | R23: Date | U23: Particulars | AB23: Folio | AC23: Amount (RM)
B24: 2023 Dec 31 | E24: Balance c/d | P24: =IF(M24="","",IFERROR(IF(ABS(ABS(M24)-ABS('Q10.13 Ans'!M24))<0.5,"✓","✗"),"✗")) | R24: 2023 Dec 31 | U24: Income statement | AB24: GJ1 | AF24: =IF(AC24="","",IFERROR(IF(ABS(ABS(AC24)-ABS('Q10.13 Ans'!AC24))<0.5,"✓","✗"),"✗"))
P25: =IF(M25="","",IFERROR(IF(ABS(ABS(M25)-ABS('Q10.13 Ans'!M25))<0.5,"✓","✗"),"✗")) | AF25: =IF(AC25="","",IFERROR(IF(ABS(ABS(AC25)-ABS('Q10.13 Ans'!AC25))<0.5,"✓","✗"),"✗"))
R26: 2024 Jan 1 | U26: Balance b/d | AF26: =IF(AC26="","",IFERROR(IF(ABS(ABS(AC26)-ABS('Q10.13 Ans'!AC26))<0.5,"✓","✗"),"✗"))
B27: 2024 Dec 31 | E27: Balance c/d | P27: =IF(M27="","",IFERROR(IF(ABS(ABS(M27)-ABS('Q10.13 Ans'!M27))<0.5,"✓","✗"),"✗")) | R27: 2024 Dec 31 | U27: Income statement | AB27: GJ2 | AF27: =IF(AC27="","",IFERROR(IF(ABS(ABS(AC27)-ABS('Q10.13 Ans'!AC27))<0.5,"✓","✗"),"✗"))
P28: =IF(M28="","",IFERROR(IF(ABS(ABS(M28)-ABS('Q10.13 Ans'!M28))<0.5,"✓","✗"),"✗")) | AF28: =IF(AC28="","",IFERROR(IF(ABS(ABS(AC28)-ABS('Q10.13 Ans'!AC28))<0.5,"✓","✗"),"✗"))
B29: 2025 Oct 1 | E29: Disposal (Van A) | L29: GJ3 | P29: =IF(M29="","",IFERROR(IF(ABS(ABS(M29)-ABS('Q10.13 Ans'!M29))<0.5,"✓","✗"),"✗")) | R29: 2025 Jan 1 | U29: Balance b/d | AF29: =IF(AC29="","",IFERROR(IF(ABS(ABS(AC29)-ABS('Q10.13 Ans'!AC29))<0.5,"✓","✗"),"✗"))
B30: Dec 31 | E30: Balance c/d | P30: =IF(M30="","",IFERROR(IF(ABS(ABS(M30)-ABS('Q10.13 Ans'!M30))<0.5,"✓","✗"),"✗")) | R30: 2025 Dec 31 | U30: Income statement | AB30: GJ4 | AF30: =IF(AC30="","",IFERROR(IF(ABS(ABS(AC30)-ABS('Q10.13 Ans'!AC30))<0.5,"✓","✗"),"✗"))
P31: =IF(M31="","",IFERROR(IF(ABS(ABS(M31)-ABS('Q10.13 Ans'!M31))<0.5,"✓","✗"),"✗")) | AF31: =IF(AC31="","",IFERROR(IF(ABS(ABS(AC31)-ABS('Q10.13 Ans'!AC31))<0.5,"✓","✗"),"✗"))
R32: 2026 Jan 1 | U32: Balance b/d | AF32: =IF(AC32="","",IFERROR(IF(ABS(ABS(AC32)-ABS('Q10.13 Ans'!AC32))<0.5,"✓","✗"),"✗"))
B34: c) Prepare the Disposal of van account. (4)
B35: Dr | E35: Disposal of Van Account | AD35: Cr
B36: Date | E36: Particulars | L36: Folio | M36: Amount (RM) | R36: Date | U36: Particulars | AB36: Folio | AC36: Amount (RM)
B37: 2025 Oct 1 | E37: Vans (Van A) | L37: GJ3 | P37: =IF(M37="","",IFERROR(IF(ABS(ABS(M37)-ABS('Q10.13 Ans'!M37))<0.5,"✓","✗"),"✗")) | R37: 2025 Oct 1 | U37: Provision for depreciation | AB37: GJ3 | AF37: =IF(AC37="","",IFERROR(IF(ABS(ABS(AC37)-ABS('Q10.13 Ans'!AC37))<0.5,"✓","✗"),"✗"))
R38: Oct 1 | U38: Bank | AB38: CB1 | AF38: =IF(AC38="","",IFERROR(IF(ABS(ABS(AC38)-ABS('Q10.13 Ans'!AC38))<0.5,"✓","✗"),"✗"))
R39: Dec 31 | U39: Income statement (loss on disposal) | AB39: GJ4 | AF39: =IF(AC39="","",IFERROR(IF(ABS(ABS(AC39)-ABS('Q10.13 Ans'!AC39))<0.5,"✓","✗"),"✗"))
P40: =IF(M40="","",IFERROR(IF(ABS(ABS(M40)-ABS('Q10.13 Ans'!M40))<0.5,"✓","✗"),"✗")) | AF40: =IF(AC40="","",IFERROR(IF(ABS(ABS(AC40)-ABS('Q10.13 Ans'!AC40))<0.5,"✓","✗"),"✗"))
B42: d) Show the Statement of Financial Position extract for vans at 31 December 2025. (2)
B43: Statement of Financial Position (extract) at 31 December 2025
E44: Particulars | R44: RM | W44: RM | AB44: RM
R45: Cost | W45: Accumulated Depreciation | AB45: Carrying Amount
E46: Non-current assets
...

Sheet Q10.9 Ans
B1: Question 10.9 (Level 1: Easy): Answers
B2: Answer sheet. Green cells hold the correct answers. Each figure is a formula linked to the question sheet, so the answers follow any change to the blue figures.
B3: Written answers are model answers: other wording that makes the same points also earns the marks.
B5: On 1 January 2024 a business bought a delivery van for RM18,000. It expects to use the van for 5 years and then sell it for RM3,000. The straight line method is used. The year end is 31 December.
B6: Figures from the question | X6: Figure
B7: Cost of van (RM) | X7: ='Q10.9'!X7 -> 18000
B8: Residual value (RM) | X8: ='Q10.9'!X8 -> 3000
B9: Useful life (years) | X9: ='Q10.9'!X9 -> 5
B12: a) Calculate the annual depreciation. (2)
B13: Annual depreciation (RM) | X13: =($X$7-$X$8)/$X$9 -> 3000
B15: b) Complete the table. (4)
B16: Year | I16: Depreciation (RM) | Q16: Accumulated depreciation (RM) | Y16: Carrying amount at end of year (RM)
B17: 2024 | I17: =$X$13 -> 3000 | Q17: =$X$13 -> 3000 | Y17: =$X$7-$X$13 -> 15000
B18: 2025 | I18: =$X$13 -> 3000 | Q18: =2*$X$13 -> 6000 | Y18: =$X$7-2*$X$13 -> 12000
B20: c) Show the Statement of Financial Position extract for the van at 31 December 2025. (2)
B21: Statement of Financial Position (extract) at 31 December 2025
E22: Particulars | R22: RM | W22: RM | AB22: RM
R23: Cost | W23: Accumulated Depreciation | AB23: Carrying Amount
E24: Non-current assets
E25: Delivery van | R25: =$X$7 -> 18000 | W25: =2*$X$13 -> 6000 | AB25: =$X$7-2*$X$13 -> 12000
B27: d) State one cause of depreciation for a delivery van. (1)
B28: Cause of depreciation | T28: ="Wear and tear" -> Wear and tear

Sheet Q10.10 Ans
B1: Question 10.10 (Level 2: Easy to medium): Answers
B2: Answer sheet. Green cells hold the correct answers. Each figure is a formula linked to the question sheet, so the answers follow any change to the blue figures.
B3: Written answers are model answers: other wording that makes the same points also earns the marks.
B5: A business bought a new machine. It paid the amounts below.
B6: Figures from the question | X6: Figure
B7: Purchase price of machine (RM) | X7: ='Q10.10'!X7 -> 22000
B8: Delivery to the factory (RM) | X8: ='Q10.10'!X8 -> 600
B9: Installation (RM) | X9: ='Q10.10'!X9 -> 900
B10: Insurance for the first year (RM) | X10: ='Q10.10'!X10 -> 400
B11: Repair after six months of use (RM) | X11: ='Q10.10'!X11 -> 250
B14: a) Calculate the cost of the machine to be shown as a non-current asset. (2)
B15: Cost of the machine (RM) | X15: =$X$7+$X$8+$X$9 -> 23500
B17: b) Classify each item as capital expenditure or revenue expenditure. (5)
B18: Purchase price | T18: ="Capital expenditure" -> Capital expenditure
B19: Delivery | T19: ="Capital expenditure" -> Capital expenditure
B20: Installation | T20: ="Capital expenditure" -> Capital expenditure
B21: Insurance for the first year | T21: ="Revenue expenditure" -> Revenue expenditure
B22: Repair after six months | T22: ="Revenue expenditure" -> Revenue expenditure
B24: c) The installation cost was recorded as an expense by mistake. State the effect on profit for the year and on non-current assets. Ignore depreciation. (2)
B25: Profit for the year is understated by (RM) | X25: =$X$9 -> 900
B26: Non-current assets are understated by (RM) | X26: =$X$9 -> 900

Sheet Q10.11 Ans
B1: Question 10.11 (Level 3: Medium): Answers
B2: Answer sheet. Green cells hold the correct answers. Each figure is a formula linked to the question sheet, so the answers follow any change to the blue figures.
B3: Written answers are model answers: other wording that makes the same points also earns the marks.
B5: The year end is 31 December.
C6: • A machine was bought on 1 April 2025 for RM12,000. Depreciation is 10% per year on cost, straight line, calculated on a monthly basis.
C7: • Loose tools were valued at RM2,000 on 1 January 2025. Tools costing RM800 were bought during 2025. On 31 December 2025 the loose tools were valued at RM2,100.
B8: Figures from the question | X8: Figure
B9: Cost of machine (RM) | X9: ='Q10.11'!X9 -> 12000
B10: Depreciation rate per year | X10: ='Q10.11'!X10 -> 0.1
B11: Months owned in 2025 | X11: ='Q10.11'!X11 -> 9
B12: Loose tools at 1 January 2025 (RM) | X12: ='Q10.11'!X12 -> 2000
B13: Loose tools bought in 2025 (RM) | X13: ='Q10.11'!X13 -> 800
B14: Loose tools at 31 December 2025 (RM) | X14: ='Q10.11'!X14 -> 2100
B17: a) Calculate depreciation on the machine for 2025 and for 2026. (3)
B18: Depreciation for 2025 (RM) | X18: =$X$9*$X$10*$X$11/12 -> 900
B19: Depreciation for 2026 (RM) | X19: =$X$9*$X$10 -> 1200
B21: b) Calculate the carrying amount of the machine at 31 December 2026. (1)
B22: Carrying amount at 31 December 2026 (RM) | X22: =$X$9-$X$18-$X$19 -> 9900
B24: c) Prepare the journal entry to record the machine depreciation for 2025. (2)
B25: Date | E25: Particulars | U25: Debit (RM) | AA25: Credit (RM)
B26: 2025 Dec 31 | E26: Income statement (depreciation) | U26: =$X$18 -> 900
E27: Provision for depreciation of machinery | AA27: =$X$18 -> 900
E28: (Being depreciation for 9 months at 10% per year on cost)
B30: d) Calculate the depreciation of loose tools for 2025. (2)
B31: Depreciation of loose tools (RM) | X31: =$X$12+$X$13-$X$14 -> 700
B33: e) Explain why the revaluation method is used for loose tools. (2)
B34: Loose tools are many small, low-cost items. Keeping a record and a depreciation calculation for each tool would take too long and cost more than it is worth. So the tools are counted and valued at each year end instead.

Sheet Q10.12 Ans
B1: Question 10.12 (Level 4: Hard): Answers
B2: Answer sheet. Green cells hold the correct answers. Each figure is a formula linked to the question sheet, so the answers follow any change to the blue figures.
B3: Written answers are model answers: other wording that makes the same points also earns the marks.
B5: On 1 January 2023 Musa bought a machine for RM40,000. It is depreciated at 25% per year, reducing balance. The year end is 31 December. On 1 January 2026 the machine was sold for RM15,000 by cheque.
B6: Figures from the question | X6: Figure
B7: Cost of machine (RM) | X7: ='Q10.12'!X7 -> 40000
B8: Reducing balance rate | X8: ='Q10.12'!X8 -> 0.25
B9: Sale proceeds on 1 January 2026 (RM) | X9: ='Q10.12'!X9 -> 15000
B12: a) Calculate the depreciation for 2023, 2024 and 2025. (3)
B13: Year | E13: Carrying amount at start (RM) | L13: Depreciation (RM) | S13: Accumulated depreciation (RM) | Z13: Carrying amount at end (RM)
B14: 2023 | E14: =$X$7 -> 40000 | L14: =ROUND($E$14*$X$8,2) -> 10000 | S14: =$L$14 -> 10000 | Z14: =$E$14-$L$14 -> 30000
B15: 2024 | E15: =$Z$14 -> 30000 | L15: =ROUND($E$15*$X$8,2) -> 7500 | S15: =$S$14+$L$15 -> 17500 | Z15: =$E$15-$L$15 -> 22500
B16: 2025 | E16: =$Z$15 -> 22500 | L16: =ROUND($E$16*$X$8,2) -> 5625 | S16: =$S$15+$L$16 -> 23125 | Z16: =$E$16-$L$16 -> 16875
B18: b) Show the carrying amount of the machine at 31 December 2025. (1)
B19: Carrying amount at 31 December 2025 (RM) | X19: =$Z$16 -> 16875
B21: c) Prepare the Machinery disposal account. (5)
B22: Dr | E22: Machinery Disposal Account | AD22: Cr
B23: Date | E23: Particulars | L23: Folio | M23: Amount (RM) | R23: Date | U23: Particulars | AB23: Folio | AC23: Amount (RM)
B24: 2026 Jan 1 | E24: Machinery | L24: GJ1 | M24: =$X$7 -> 40000 | R24: 2026 Jan 1 | U24: Provision for depreciation | AB24: GJ1 | AC24: =$S$16 -> 23125
R25: Jan 1 | U25: Bank | AB25: CB1 | AC25: =$X$9 -> 15000
R26: Dec 31 | U26: Income statement (loss on disposal) | AB26: GJ2 | AC26: =$Z$16-$X$9 -> 1875
M27: =SUM(M24:M26) -> 40000 | AC27: =SUM(AC24:AC26) -> 40000
B29: d) State where the result of the disposal appears in the financial statements. (1)
B30: The loss on disposal is shown as | T30: ="Expense in the SPL" -> Expense in the SPL

Sheet Q10.13 Ans
B1: Question 10.13 (Level 5: Challenge): Answers
B2: Answer sheet. Green cells hold the correct answers. Each figure is a formula linked to the question sheet, so the answers follow any change to the blue figures.
B3: Written answers are model answers: other wording that makes the same points also earns the marks.
B5: Kwame's year ends on 31 December. He depreciates vans at 20% per year on cost, straight line. A full year's depreciation is charged in the year of purchase and none in the year of sale.
C6: • 1 January 2023: bought Van A for RM25,000.
C7: • 1 July 2024: bought Van B for RM30,000.
C8: • 1 October 2025: sold Van A for RM12,000, paid by cheque.
B9: Figures from the question | X9: Figure
B10: Cost of Van A (RM) | X10: ='Q10.13'!X10 -> 25000
B11: Cost of Van B (RM) | X11: ='Q10.13'!X11 -> 30000
B12: Depreciation rate on cost | X12: ='Q10.13'!X12 -> 0.2
B13: Sale proceeds of Van A (RM) | X13: ='Q10.13'!X13 -> 12000
B16: a) Calculate the depreciation charge for 2023, 2024 and 2025. (3)
B17: Depreciation for 2023 (RM) | X17: =$X$10*$X$12 -> 5000
B18: Depreciation for 2024 (RM) | X18: =($X$10+$X$11)*$X$12 -> 11000
B19: Depreciation for 2025 (RM) | X19: =$X$11*$X$12 -> 6000
B21: b) Prepare the Provision for depreciation of vans account for 2023, 2024 and 2025. (6)
B22: Dr | E22: Provision for Depreciation of Vans Account | AD22: Cr
B23: Date | E23: Particulars | L23: Folio | M23: Amount (RM) | R23: Date | U23: Particulars | AB23: Folio | AC23: Amount (RM)
B24: 2023 Dec 31 | E24: Balance c/d | M24: =$X$17 -> 5000 | R24: 2023 Dec 31 | U24: Income statement | AB24: GJ1 | AC24: =$X$17 -> 5000
M25: =SUM(M24:M24) -> 5000 | AC25: =SUM(AC24:AC24) -> 5000
R26: 2024 Jan 1 | U26: Balance b/d | AC26: =$X$17 -> 5000
B27: 2024 Dec 31 | E27: Balance c/d | M27: =$X$17+$X$18 -> 16000 | R27: 2024 Dec 31 | U27: Income statement | AB27: GJ2 | AC27: =$X$18 -> 11000
M28: =SUM(M26:M27) -> 16000 | AC28: =SUM(AC26:AC27) -> 16000
B29: 2025 Oct 1 | E29: Disposal (Van A) | L29: GJ3 | M29: =2*$X$10*$X$12 -> 10000 | R29: 2025 Jan 1 | U29: Balance b/d | AC29: =$X$17+$X$18 -> 16000
B30: Dec 31 | E30: Balance c/d | M30: =$X$17+$X$18+$X$19-2*$X$10*$X$12 -> 12000 | R30: 2025 Dec 31 | U30: Income statement | AB30: GJ4 | AC30: =$X$19 -> 6000
M31: =SUM(M29:M30) -> 22000 | AC31: =SUM(AC29:AC30) -> 22000
R32: 2026 Jan 1 | U32: Balance b/d | AC32: =$X$17+$X$18+$X$19-2*$X$10*$X$12 -> 12000
B34: c) Prepare the Disposal of van account. (4)
B35: Dr | E35: Disposal of Van Account | AD35: Cr
B36: Date | E36: Particulars | L36: Folio | M36: Amount (RM) | R36: Date | U36: Particulars | AB36: Folio | AC36: Amount (RM)
B37: 2025 Oct 1 | E37: Vans (Van A) | L37: GJ3 | M37: =$X$10 -> 25000 | R37: 2025 Oct 1 | U37: Provision for depreciation | AB37: GJ3 | AC37: =2*$X$10*$X$12 -> 10000
R38: Oct 1 | U38: Bank | AB38: CB1 | AC38: =$X$13 -> 12000
R39: Dec 31 | U39: Income statement (loss on disposal) | AB39: GJ4 | AC39: =$X$10-2*$X$10*$X$12-$X$13 -> 3000
M40: =SUM(M37:M39) -> 25000 | AC40: =SUM(AC37:AC39) -> 25000
B42: d) Show the Statement of Financial Position extract for vans at 31 December 2025. (2)
B43: Statement of Financial Position (extract) at 31 December 2025
E44: Particulars | R44: RM | W44: RM | AB44: RM
R45: Cost | W45: Accumulated Depreciation | AB45: Carrying Amount
E46: Non-current assets
...
