Workbook

Sheet Read Me
A1: Statement of Profit or Loss and Statement of Financial Position
A2: Senior 1 Accounting. Free to use and share.
B4: How to use this workbook
B5: 1. Start with the worked example sheets. Change any blue number and watch every answer update.
B6: 2. Then try the Practice sheet. Type your answers in the yellow cells.
B7: 3. The Check column tells you 'Correct' or 'Try again' as soon as you type.
B8: 4. The Answers sheet is hidden. When you finish, right-click any sheet tab and choose Unhide to see full answers.
B10: Colour key
B11: Blue text = an input you can change.
B12: Black text = a formula. Do not type over it.
B13: Yellow cell = your answer goes here.
B15: Worked example: Amina Stores (notes section 6). Practice: Ben's Bikes (Model Question FS.6).

Sheet Trial Balance
A1: Amina Stores: Trial balance at 31 December 2025
A3: Account | B3: Dr $ | C3: Cr $
A4: Revenue | C4: 110000
A5: Purchases | B5: 62000
A6: Sales returns | B6: 1500
A7: Purchases returns | C7: 1200
A8: Carriage inwards | B8: 800
A9: Carriage outwards | B9: 600
A10: Inventory at 1 January 2025 | B10: 8000
A11: Wages | B11: 14000
A12: Rent | B12: 5500
A13: Insurance | B13: 1800
A14: General expenses | B14: 2100
A15: Discount allowed | B15: 400
A16: Discount received | C16: 500
A17: Irrecoverable debts | B17: 700
A18: Premises at cost | B18: 60000
A19: Equipment at cost | B19: 20000
A20: Provision for depreciation: equipment | C20: 6000
A21: Trade receivables | B21: 12000
A22: Allowance for irrecoverable debts | C22: 400
A23: Trade payables | C23: 7500
A24: Bank | B24: 4300
A25: Cash | B25: 200
A26: Loan (repayable 2030) | C26: 10000
A27: Capital | C27: 67300
A28: Drawings | B28: 9000
A29: Totals | B29: =SUM(B4:B28) -> 202900 | C29: =SUM(C4:C28) -> 202900 | D29: =IF(B29=C29,"Trial balance agrees","Does not agree") -> Trial balance agrees

Sheet Adjustments
A1: Amina Stores: Additional information at 31 December 2025
A3: 1. Closing inventory | B3: 9500
A4: 2. Rent owing (accrued) | B4: 500
A5: 3. Insurance prepaid | B5: 300
A6: 4. Allowance for irrecoverable debts (% of trade receivables) | B6: 0.05
A7: 5. Equipment depreciation (% of cost, straight line) | B7: 0.1
A8: 6. Loan interest rate per year (none paid) | B8: 0.05

Sheet SPL
A1: Amina Stores: Statement of Profit or Loss for the year ended 31 December 2025
B3: $ | C3: $
A4: Revenue | C4: ='Trial Balance'!$C$4 -> 110000
A5: Less: Sales returns | C5: ='Trial Balance'!$B$6 -> 1500
A6: Net revenue | C6: =C4-C5 -> 108500
A7: Less: Cost of sales
A8: Opening inventory | B8: ='Trial Balance'!$B$10 -> 8000
A9: Add: Purchases | B9: ='Trial Balance'!$B$5 -> 62000
A10: Less: Purchases returns | B10: =-'Trial Balance'!$C$7 -> -1200
A11: Add: Carriage inwards | B11: ='Trial Balance'!$B$8 -> 800
A12: Cost of goods available for sale | B12: =SUM(B8:B11) -> 69600
A13: Less: Closing inventory | B13: =-Adjustments!$B$3 -> -9500
A14: Cost of sales | C14: =B12+B13 -> 60100
A15: Gross profit | C15: =C6-C14 -> 48400
A16: Add: Other income
A17: Discount received | B17: ='Trial Balance'!$C$16 -> 500
A18: Decrease in allowance for irrecoverable debts | B18: =MAX(-(ROUND('Trial Balance'!$B$21*Adjustments!$B$6,2)-'Trial Balance'!$C$22),0) -> 0
A19: Total other income | C19: =B17+B18 -> 500
C20: =C15+C19 -> 48900
A21: Less: Expenses
A22: Wages | B22: ='Trial Balance'!$B$11 -> 14000
A23: Rent (paid + owing) | B23: ='Trial Balance'!$B$12+Adjustments!$B$4 -> 6000
A24: Insurance (paid - prepaid) | B24: ='Trial Balance'!$B$13-Adjustments!$B$5 -> 1500
A25: General expenses | B25: ='Trial Balance'!$B$14 -> 2100
A26: Carriage outwards | B26: ='Trial Balance'!$B$9 -> 600
A27: Discount allowed | B27: ='Trial Balance'!$B$15 -> 400
A28: Irrecoverable debts | B28: ='Trial Balance'!$B$17 -> 700
A29: Increase in allowance for irrecoverable debts | B29: =MAX(ROUND('Trial Balance'!$B$21*Adjustments!$B$6,2)-'Trial Balance'!$C$22,0) -> 200
A30: Depreciation: equipment | B30: ='Trial Balance'!$B$19*Adjustments!$B$7 -> 2000
A31: Loan interest | B31: ='Trial Balance'!$C$26*Adjustments!$B$8 -> 500
A32: Total expenses | C32: =SUM(B22:B31) -> 28000
A33: Profit for the year | C33: =C20-C32 -> 20900

Sheet SFP
A1: Amina Stores: Statement of Financial Position at 31 December 2025
B3: Cost $ | C3: Acc. dep. $ | D3: NBV $
A4: Non-current assets
A5: Premises | B5: ='Trial Balance'!$B$18 -> 60000 | C5: =0 -> 0 | D5: =B5-C5 -> 60000
A6: Equipment | B6: ='Trial Balance'!$B$19 -> 20000 | C6: ='Trial Balance'!$C$20+SPL!B30 -> 8000 | D6: =B6-C6 -> 12000
A7: Total non-current assets | B7: =B5+B6 -> 80000 | C7: =C5+C6 -> 8000 | D7: =D5+D6 -> 72000
A8: Current assets
A9: Inventory | C9: =Adjustments!$B$3 -> 9500
A10: Trade receivables | B10: ='Trial Balance'!$B$21 -> 12000
A11: Less: Allowance for irrecoverable debts | B11: =ROUND('Trial Balance'!$B$21*Adjustments!$B$6,2) -> 600 | C11: =B10-B11 -> 11400
A12: Other receivables (insurance prepaid) | C12: =Adjustments!$B$5 -> 300
A13: Bank | C13: ='Trial Balance'!$B$24 -> 4300
A14: Cash | C14: ='Trial Balance'!$B$25 -> 200
A15: Total current assets | C15: =SUM(C9:C14) -> 25700
A16: Current liabilities
A17: Trade payables | C17: ='Trial Balance'!$C$23 -> 7500
A18: Other payables (rent owing + loan interest owing) | C18: =Adjustments!$B$4+SPL!B31 -> 1000
A19: Total current liabilities | C19: =C17+C18 -> 8500
A20: Net current assets (working capital) | D20: =C15-C19 -> 17200
D21: =D7+D20 -> 89200
A22: Non-current liabilities
A23: Loan | D23: ='Trial Balance'!$C$26 -> 10000
A24: Net assets | D24: =D21-D23 -> 79200
A26: Capital
A27: Opening capital | D27: ='Trial Balance'!$C$27 -> 67300
A28: Add: Profit for the year | D28: =SPL!C33 -> 20900
D29: =D27+D28 -> 88200
A30: Less: Drawings | D30: ='Trial Balance'!$B$28 -> 9000
A31: Closing capital | D31: =D29-D30 -> 79200
A33: Check | D33: =IF(ROUND(D24-D31,2)=0,"Balances","Does not balance") -> Balances

Sheet Practice
A1: Practice: Ben's Bikes (Model Question FS.6)
A2: Type your answers in the yellow cells. The Check column marks them.
A3: Prepare both statements on paper, then enter the key figures below.
A5: Trial balance at 30 June 2026
A6: Account | B6: Dr $ | C6: Cr $
A7: Revenue | C7: 82000
A8: Purchases | B8: 45000
A9: Sales returns | B9: 800
A10: Purchases returns | C10: 900
A11: Carriage inwards | B11: 400
A12: Inventory at 1 July 2025 | B12: 6200
A13: Wages | B13: 12600
A14: Electricity | B14: 2300
A15: Insurance | B15: 1600
A16: Advertising | B16: 1200
A17: Irrecoverable debts | B17: 350
A18: Rent received | C18: 2400
A19: Motor vehicles at cost | B19: 24000
A20: Provision for depreciation: motor vehicles | C20: 6000
A21: Fixtures at cost | B21: 8000
A22: Provision for depreciation: fixtures | C22: 2000
A23: Trade receivables | B23: 9000
A24: Allowance for irrecoverable debts | C24: 500
A25: Trade payables | C25: 5300
A26: Bank | B26: 3150
A27: Capital | C27: 23000
A28: Drawings | B28: 7500
A29: Totals | B29: =SUM(B7:B28) -> 122100 | C29: =SUM(C7:C28) -> 122100 | D29: =IF(B29=C29,"Trial balance agrees","Does not agree") -> Trial balance agrees
A31: Additional information at 30 June 2026
A32: 1. Closing inventory | B32: 7100
A33: 2. Electricity owing | B33: 250
A34: 3. Insurance prepaid | B34: 400
A35: 4. Rent received in advance | B35: 200
A36: 5. Allowance (% of trade receivables) | B36: 0.04
A37: 6. Motor vehicles depreciation (reducing balance) | B37: 0.2
A38: 7. Fixtures depreciation (straight line on cost) | B38: 0.1
A40: Question | B40: Your answer | C40: Check
A41: a) Statement of Profit or Loss
A42: Net revenue | C42: =IF(B42="","",IFERROR(IF(ABS(B42-Answers!B42)<0.5,"Correct","Try again"),"Enter a number"))
A43: Cost of goods available for sale (before closing inventory) | C43: =IF(B43="","",IFERROR(IF(ABS(B43-Answers!B43)<0.5,"Correct","Try again"),"Enter a number"))
...

Sheet Answers
A1: Practice: Ben's Bikes (Model Question FS.6): Answers
A2: Every answer is a formula linked to the Practice sheet data.
A40: Question | B40: Answer
A41: a) Statement of Profit or Loss
A42: Net revenue | B42: =(Practice!$C$7-Practice!$B$9) -> 81200
A43: Cost of goods available for sale (before closing inventory) | B43: =Practice!$B$12+Practice!$B$8-Practice!$C$10+Practice!$B$11 -> 50700
A44: Cost of sales | B44: =(Practice!$B$12+Practice!$B$8-Practice!$C$10+Practice!$B$11-Practice!$B$32) -> 43600
A45: Gross profit | B45: =((Practice!$C$7-Practice!$B$9)-(Practice!$B$12+Practice!$B$8-Practice!$C$10+Practice!$B$11-Practice!$B$32)) -> 37600
A46: Rent received (income for the year) | B46: =(Practice!$C$18-Practice!$B$35) -> 2200
A47: Decrease in allowance for irrecoverable debts | B47: =MAX(-(ROUND(Practice!$B$23*Practice!$B$36,2)-Practice!$C$24),0) -> 140
A48: Electricity expense | B48: =Practice!$B$14+Practice!$B$33 -> 2550
A49: Insurance expense | B49: =Practice!$B$15-Practice!$B$34 -> 1200
A50: Depreciation: motor vehicles | B50: =((Practice!$B$19-Practice!$C$20)*Practice!$B$37) -> 3600
A51: Depreciation: fixtures | B51: =(Practice!$B$21*Practice!$B$38) -> 800
A52: Total expenses | B52: =(Practice!$B$13+Practice!$B$14+Practice!$B$33+Practice!$B$15-Practice!$B$34+Practice!$B$16+Practice!$B$17+MAX((ROUND(Practice!$B$23*Practice!$B$36,2)-Practice!$C$24),0)+((Practice!$B$19-Practice!$C$20)*Practice!$B$37)+(Practice!$B$21*Practice!$B$38)) -> 22300
A53: Profit for the year | B53: =(((Practice!$C$7-Practice!$B$9)-(Practice!$B$12+Practice!$B$8-Practice!$C$10+Practice!$B$11-Practice!$B$32))+(Practice!$C$18-Practice!$B$35)+MAX(-(ROUND(Practice!$B$23*Practice!$B$36,2)-Practice!$C$24),0)-(Practice!$B$13+Practice!$B$14+Practice!$B$33+Practice!$B$15-Practice!$B$34+Practice!$B$16+Practice!$B$17+MAX((ROUND(Practice!$B$23*Practice!$B$36,2)-Practice!$C$24),0)+((Practice!$B$19-Practice!$C$20)*Practice!$B$37)+(Practice!$B$21*Practice!$B$38))) -> 17640
A54: b) Statement of Financial Position
A55: Motor vehicles: NBV | B55: =Practice!$B$19-Practice!$C$20-((Practice!$B$19-Practice!$C$20)*Practice!$B$37) -> 14400
A56: Fixtures: NBV | B56: =Practice!$B$21-Practice!$C$22-(Practice!$B$21*Practice!$B$38) -> 5200
A57: Total non-current assets | B57: =(Practice!$B$19-Practice!$C$20-((Practice!$B$19-Practice!$C$20)*Practice!$B$37)+Practice!$B$21-Practice!$C$22-(Practice!$B$21*Practice!$B$38)) -> 19600
A58: Net trade receivables (after allowance) | B58: =Practice!$B$23-ROUND(Practice!$B$23*Practice!$B$36,2) -> 8640
A59: Total current assets | B59: =(Practice!$B$32+Practice!$B$23-ROUND(Practice!$B$23*Practice!$B$36,2)+Practice!$B$34+Practice!$B$26) -> 19290
A60: Other payables | B60: =Practice!$B$33+Practice!$B$35 -> 450
A61: Total current liabilities | B61: =(Practice!$C$25+Practice!$B$33+Practice!$B$35) -> 5750
A62: Net current assets (working capital) | B62: =(Practice!$B$32+Practice!$B$23-ROUND(Practice!$B$23*Practice!$B$36,2)+Practice!$B$34+Practice!$B$26)-(Practice!$C$25+Practice!$B$33+Practice!$B$35) -> 13540
A63: Net assets | B63: =(Practice!$B$19-Practice!$C$20-((Practice!$B$19-Practice!$C$20)*Practice!$B$37)+Practice!$B$21-Practice!$C$22-(Practice!$B$21*Practice!$B$38))+(Practice!$B$32+Practice!$B$23-ROUND(Practice!$B$23*Practice!$B$36,2)+Practice!$B$34+Practice!$B$26)-(Practice!$C$25+Practice!$B$33+Practice!$B$35) -> 33140
A64: Closing capital | B64: =Practice!$C$27+(((Practice!$C$7-Practice!$B$9)-(Practice!$B$12+Practice!$B$8-Practice!$C$10+Practice!$B$11-Practice!$B$32))+(Practice!$C$18-Practice!$B$35)+MAX(-(ROUND(Practice!$B$23*Practice!$B$36,2)-Practice!$C$24),0)-(Practice!$B$13+Practice!$B$14+Practice!$B$33+Practice!$B$15-Practice!$B$34+Practice!$B$16+Practice!$B$17+MAX((ROUND(Practice!$B$23*Practice!$B$36,2)-Practice!$C$24),0)+((Practice!$B$19-Practice!$C$20)*Practice!$B$37)+(Practice!$B$21*Practice!$B$38)))-Practice!$B$28 -> 33140
