Workbook

Sheet Read Me
B1: Mock Test: Senior 1 Accounting (2 hours, 100 marks)
B2: Senior 1 Accounting. Free to use and share. Not for sale.
B4: How to use this workbook
B5: 1. Sit the paper in 2 hours without notes. Section A: 10 marks. Section B: 40 marks. Section C: 50 marks.
B6: 2. Type answers in the yellow cells on the blue Mock tabs. The Scores tab adds up your correct cells.
B7: 3. The green Ans tabs are the mark scheme. Written answers are marked by comparing with the model answer.
B8: 4. The printed paper is model-questions/Mock_Test.md (or pdf/Mock_Test.pdf).
B10: Colour key
B11: 1000 | H11: Blue figure: data from the question. Teachers may change it to make a new version.
B12: 1000 | H12: Black figure: a formula. Do not type over it.
H13: Yellow cell: type your answer here (numbers only; enter 0 for nil).
B14: 1000 | H14: Green cell: the correct answer (Ans tabs).
B16: Formats used
B17: Journal: Date | Particulars | Debit | Credit. The first row shows the year, with RM under Debit and Credit.
B18: Ledger account: Dr side and Cr side, each with Date | Particulars | Folio | Amount. The first row under the headings shows the year, with RM in the Amount column; entries then show the month and day. Folio: GJ = general journal, CB = cash book.
B19: Statement of Profit or Loss: marker (Add / Less) | Particulars | RM | RM | RM.
B20: Statement of Financial Position: the same, with Cost | Accumulated Depreciation | Carrying Amount under the RM headings.
B22: Sheets in this workbook
B23: Sheet | I23: What it is
B24: Scores | I24: Your marks for every section of the mock test.
B25: Mock A | I25: Section A: multiple choice, 10 marks. Answers: Mock A Ans (green tab).
B26: Mock B1 | I26: Section B, Chapter 8: 10 marks. Answers: Mock B1 Ans (green tab).
B27: Mock B2 | I27: Section B, Chapter 10: 10 marks. Answers: Mock B2 Ans (green tab).
B28: Mock B3 | I28: Section B, Chapter 11: 10 marks. Answers: Mock B3 Ans (green tab).
B29: Mock B4 | I29: Section B, Chapter 12: 10 marks. Answers: Mock B4 Ans (green tab).
B30: Mock C | I30: Section C, financial statements: 50 marks. Answers: Mock C Ans (green tab).

Sheet Scores
B1: Mock test: your scores
B2: Marks come from the ✓ cells on each blue Mock tab.
B3: Section | O3: Answer cells correct | X3: Answer cells in total
B4: Section A: multiple choice, 10 marks | O4: =COUNTIF('Mock A'!B1:AH400,"✓") -> 0 | X4: 10
B5: Section B, Chapter 8: 10 marks | O5: =COUNTIF('Mock B1'!B1:AH400,"✓") -> 0 | X5: 10
B6: Section B, Chapter 10: 10 marks | O6: =COUNTIF('Mock B2'!B1:AH400,"✓") -> 0 | X6: 11
B7: Section B, Chapter 11: 10 marks | O7: =COUNTIF('Mock B3'!B1:AH400,"✓") -> 0 | X7: 13
B8: Section B, Chapter 12: 10 marks | O8: =COUNTIF('Mock B4'!B1:AH400,"✓") -> 0 | X8: 7
B9: Section C, financial statements: 50 marks | O9: =COUNTIF('Mock C'!B1:AH400,"✓") -> 0 | X9: 61
B10: Total | O10: =$O$4+$O$5+$O$6+$O$7+$O$8+$O$9 -> 0 | X10: 112
B11: Each answer cell is worth roughly one mark in Sections A and B. Section C has more cells than marks, so use the Ans tabs as the mark scheme for the final mark out of 100.

Sheet Mock A
B1: Section A: multiple choice, 10 marks
B2: Type your answers in the yellow cells. Numbers only: no RM, no commas. Enter 0 where the answer is nil. ✓ = correct, ✗ = try again.
B3: Your score: | H3: =COUNTIF(B4:AG75,"✓")&" correct out of 10 answer cells" -> 0 correct out of 10 answer cells
B5: Section A: multiple choice. 1 mark each. Choose A, B, C or D.
B6: 1. Which double entry writes off an irrecoverable debt?
C7: A. Debit irrecoverable debts, credit trade receivable
C8: B. Debit trade receivable, credit irrecoverable debts
C9: C. Debit bank, credit irrecoverable debts
C10: D. Debit allowance for irrecoverable debts, credit bank
B11: Your answer | AC11: =IF(T11="","",IF(LOWER(TRIM(T11))=LOWER('Mock A Ans'!T11),"✓","✗"))
B13: 2. Trade receivables are RM40,000. The allowance is to be 5%. The allowance brought forward is RM2,500. What is the effect on the Statement of Profit or Loss?
C14: A. Expense of RM2,000
C15: B. Income of RM500
C16: C. Expense of RM500
C17: D. Income of RM2,000
B18: Your answer | AC18: =IF(T18="","",IF(LOWER(TRIM(T18))=LOWER('Mock A Ans'!T18),"✓","✗"))
B20: 3. A machine costs RM30,000, has a residual value of RM3,000 and a useful life of 6 years. What is the annual straight line depreciation?
C21: A. RM5,000
C22: B. RM3,000
C23: C. RM4,500
C24: D. RM5,500
B25: Your answer | AC25: =IF(T25="","",IF(LOWER(TRIM(T25))=LOWER('Mock A Ans'!T25),"✓","✗"))
B27: 4. Equipment costs RM25,000 and is depreciated at 20% per year, reducing balance. What is the depreciation charge in Year 2?
C28: A. RM5,000
C29: B. RM3,200
C30: C. RM20,000
C31: D. RM4,000
B32: Your answer | AC32: =IF(T32="","",IF(LOWER(TRIM(T32))=LOWER('Mock A Ans'!T32),"✓","✗"))
B34: 5. A vehicle cost RM20,000. Accumulated depreciation is RM12,000. It is sold for RM9,500. What is the result?
C35: A. Profit of RM1,500
C36: B. Loss of RM1,500
C37: C. Profit of RM9,500
C38: D. Loss of RM8,000
B39: Your answer | AC39: =IF(T39="","",IF(LOWER(TRIM(T39))=LOWER('Mock A Ans'!T39),"✓","✗"))
B41: 6. Rent paid during the year was RM7,200. At the year end RM600 was owing. What is the rent expense?
C42: A. RM6,600
C43: B. RM7,200
C44: C. RM7,800
C45: D. RM8,400
B46: Your answer | AC46: =IF(T46="","",IF(LOWER(TRIM(T46))=LOWER('Mock A Ans'!T46),"✓","✗"))
...

Sheet Mock B1
B1: Section B, Chapter 8: 10 marks
B2: Type your answers in the yellow cells. Numbers only: no RM, no commas. Enter 0 where the answer is nil. ✓ = correct, ✗ = try again.
B3: Your score: | H3: =COUNTIF(B4:AG35,"✓")&" correct out of 10 answer cells" -> 0 correct out of 10 answer cells
B5: Lim's year ends on 31 December 2025. Trade receivables are RM45,600 before writing off a debt of RM1,600 owed by Tan, who is bankrupt. The allowance for irrecoverable debts brought forward is RM1,500. It is to be 4% of the remaining trade receivables.
B6: Figures from the question | X6: Figure
B7: Trade receivables before writing off Tan (RM) | X7: 45600
B8: Tan's debt (RM) | X8: 1600
B9: Allowance brought forward (RM) | X9: 1500
B10: Allowance rate | X10: 0.04
B13: a) Calculate trade receivables after the write-off, the new allowance and the change in the allowance. (3)
B14: Trade receivables after the write-off (RM) | AC14: =IF(X14="","",IFERROR(IF(ABS(ABS(X14)-ABS('Mock B1 Ans'!X14))<0.5,"✓","✗"),"✗"))
B15: New allowance (RM) | AC15: =IF(X15="","",IFERROR(IF(ABS(ABS(X15)-ABS('Mock B1 Ans'!X15))<0.5,"✓","✗"),"✗"))
B16: Increase in the allowance (RM) | AC16: =IF(X16="","",IFERROR(IF(ABS(ABS(X16)-ABS('Mock B1 Ans'!X16))<0.5,"✓","✗"),"✗"))
B18: b) Prepare the journal entries to write off Tan's debt and to record the change in the allowance. (4)
B19: Date | E19: Particulars | U19: Debit | AA19: Credit
B20: 2025 | U20: RM | AA20: RM
B21: Dec 31 | E21: Irrecoverable debts | Z21: =IF(U21="","",IFERROR(IF(ABS(ABS(U21)-ABS('Mock B1 Ans'!U21))<0.5,"✓","✗"),"✗"))
E22: Tan | AF22: =IF(AA22="","",IFERROR(IF(ABS(ABS(AA22)-ABS('Mock B1 Ans'!AA22))<0.5,"✓","✗"),"✗"))
E23: (Being debt written off: customer bankrupt)
B24: Dec 31 | E24: Income statement | Z24: =IF(U24="","",IFERROR(IF(ABS(ABS(U24)-ABS('Mock B1 Ans'!U24))<0.5,"✓","✗"),"✗"))
E25: Allowance for irrecoverable debts | AF25: =IF(AA25="","",IFERROR(IF(ABS(ABS(AA25)-ABS('Mock B1 Ans'!AA25))<0.5,"✓","✗"),"✗"))
E26: (Being increase in the allowance)
B28: c) Show the Statement of Financial Position extract for trade receivables. (3)
B29: Statement of Financial Position (extract) at 31 December 2025
E30: Particulars | R30: RM | W30: RM | AB30: RM
R31: Cost | W31: Accumulated Depreciation | AB31: Carrying Amount
E32: Current assets
E33: Trade receivables | V33: =IF(R33="","",IFERROR(IF(ABS(ABS(R33)-ABS('Mock B1 Ans'!R33))<0.5,"✓","✗"),"✗"))
B34: Less: | E34: Allowance for irrecoverable debts | V34: =IF(R34="","",IFERROR(IF(ABS(ABS(R34)-ABS('Mock B1 Ans'!R34))<0.5,"✓","✗"),"✗")) | AA34: =IF(W34="","",IFERROR(IF(ABS(ABS(W34)-ABS('Mock B1 Ans'!W34))<0.5,"✓","✗"),"✗"))

Sheet Mock B2
B1: Section B, Chapter 10: 10 marks
B2: Type your answers in the yellow cells. Numbers only: no RM, no commas. Enter 0 where the answer is nil. ✓ = correct, ✗ = try again.
B3: Your score: | H3: =COUNTIF(B4:AG29,"✓")&" correct out of 11 answer cells" -> 0 correct out of 11 answer cells
B5: On 1 January 2024 a business bought a van for RM48,000. It is depreciated at 25% per year, reducing balance. The year ends on 31 December. On 1 January 2026 the van was sold for RM25,000 by cheque.
B6: Figures from the question | X6: Figure
B7: Cost of van (RM) | X7: 48000
B8: Reducing balance rate | X8: 0.25
B9: Sale proceeds (RM) | X9: 25000
B12: a) Calculate the depreciation for 2024 and 2025 and the carrying amount at 31 December 2025. (3)
B13: Depreciation for 2024 (RM) | AC13: =IF(X13="","",IFERROR(IF(ABS(ABS(X13)-ABS('Mock B2 Ans'!X13))<0.5,"✓","✗"),"✗"))
B14: Depreciation for 2025 (RM) | AC14: =IF(X14="","",IFERROR(IF(ABS(ABS(X14)-ABS('Mock B2 Ans'!X14))<0.5,"✓","✗"),"✗"))
B15: Carrying amount at 31 December 2025 (RM) | AC15: =IF(X15="","",IFERROR(IF(ABS(ABS(X15)-ABS('Mock B2 Ans'!X15))<0.5,"✓","✗"),"✗"))
B17: b) Prepare the Disposal of van account. (5)
B18: Dr | E18: Disposal of Van Account | AD18: Cr
B19: Date | E19: Particulars | L19: Folio | M19: Amount | R19: Date | U19: Particulars | AB19: Folio | AC19: Amount
B20: 2026 | M20: RM | R20: 2026 | AC20: RM
B21: Jan 1 | E21: Van | L21: GJ1 | P21: =IF(M21="","",IFERROR(IF(ABS(ABS(M21)-ABS('Mock B2 Ans'!M21))<0.5,"✓","✗"),"✗")) | R21: Jan 1 | U21: Provision for depreciation | AB21: GJ1 | AF21: =IF(AC21="","",IFERROR(IF(ABS(ABS(AC21)-ABS('Mock B2 Ans'!AC21))<0.5,"✓","✗"),"✗"))
R22: Jan 1 | U22: Bank | AB22: CB1 | AF22: =IF(AC22="","",IFERROR(IF(ABS(ABS(AC22)-ABS('Mock B2 Ans'!AC22))<0.5,"✓","✗"),"✗"))
R23: Dec 31 | U23: Income statement (loss on disposal) | AB23: GJ2 | AF23: =IF(AC23="","",IFERROR(IF(ABS(ABS(AC23)-ABS('Mock B2 Ans'!AC23))<0.5,"✓","✗"),"✗"))
P24: =IF(M24="","",IFERROR(IF(ABS(ABS(M24)-ABS('Mock B2 Ans'!M24))<0.5,"✓","✗"),"✗")) | AF24: =IF(AC24="","",IFERROR(IF(ABS(ABS(AC24)-ABS('Mock B2 Ans'!AC24))<0.5,"✓","✗"),"✗"))
B26: c) State where the loss appears, and name the concept that requires depreciation. (2)
B27: The loss on disposal is shown as | AC27: =IF(T27="","",IF(LOWER(TRIM(T27))=LOWER('Mock B2 Ans'!T27),"✓","✗"))
B28: Concept that requires depreciation | AC28: =IF(T28="","",IF(OR(LOWER(TRIM(T28))="accruals",LOWER(TRIM(T28))="prudence"),"✓","✗"))

Sheet Mock B3
B1: Section B, Chapter 11: 10 marks
B2: Type your answers in the yellow cells. Numbers only: no RM, no commas. Enter 0 where the answer is nil. ✓ = correct, ✗ = try again.
B3: Your score: | H3: =COUNTIF(B4:AG40,"✓")&" correct out of 13 answer cells" -> 0 correct out of 13 answer cells
B5: Wong's year ends on 31 December 2025.
C6: • Rent is RM900 per month. RM9,900 was paid during the year.
C7: • Insurance of RM400 was prepaid at 1 January 2025. On 1 April 2025 RM3,000 was paid for 12 months.
B8: Figures from the question | X8: Figure
B9: Rent per month (RM) | X9: 900
B10: Rent paid in 2025 (RM) | X10: 9900
B11: Insurance prepaid at 1 January 2025 (RM) | X11: 400
B12: Insurance paid on 1 April 2025 (RM) | X12: 3000
B13: Months of that policy used in 2025 | X13: 9
B16: a) Calculate the rent expense, the rent owing, the insurance expense and the insurance prepaid. (4)
B17: Rent expense (RM) | AC17: =IF(X17="","",IFERROR(IF(ABS(ABS(X17)-ABS('Mock B3 Ans'!X17))<0.5,"✓","✗"),"✗"))
B18: Rent owing (RM) | AC18: =IF(X18="","",IFERROR(IF(ABS(ABS(X18)-ABS('Mock B3 Ans'!X18))<0.5,"✓","✗"),"✗"))
B19: Insurance expense (RM) | AC19: =IF(X19="","",IFERROR(IF(ABS(ABS(X19)-ABS('Mock B3 Ans'!X19))<0.5,"✓","✗"),"✗"))
B20: Insurance prepaid (RM) | AC20: =IF(X20="","",IFERROR(IF(ABS(ABS(X20)-ABS('Mock B3 Ans'!X20))<0.5,"✓","✗"),"✗"))
B22: b) Prepare the Insurance account for the year. (4)
B23: Dr | E23: Insurance Account | AD23: Cr
B24: Date | E24: Particulars | L24: Folio | M24: Amount | R24: Date | U24: Particulars | AB24: Folio | AC24: Amount
B25: 2025 | M25: RM | R25: 2025 | AC25: RM
B26: Jan 1 | E26: Balance b/d | P26: =IF(M26="","",IFERROR(IF(ABS(ABS(M26)-ABS('Mock B3 Ans'!M26))<0.5,"✓","✗"),"✗")) | R26: Dec 31 | U26: Profit or loss | AB26: GJ1 | AF26: =IF(AC26="","",IFERROR(IF(ABS(ABS(AC26)-ABS('Mock B3 Ans'!AC26))<0.5,"✓","✗"),"✗"))
B27: Apr 1 | E27: Bank | L27: CB1 | P27: =IF(M27="","",IFERROR(IF(ABS(ABS(M27)-ABS('Mock B3 Ans'!M27))<0.5,"✓","✗"),"✗")) | R27: Dec 31 | U27: Balance c/d | AF27: =IF(AC27="","",IFERROR(IF(ABS(ABS(AC27)-ABS('Mock B3 Ans'!AC27))<0.5,"✓","✗"),"✗"))
P28: =IF(M28="","",IFERROR(IF(ABS(ABS(M28)-ABS('Mock B3 Ans'!M28))<0.5,"✓","✗"),"✗")) | AF28: =IF(AC28="","",IFERROR(IF(ABS(ABS(AC28)-ABS('Mock B3 Ans'!AC28))<0.5,"✓","✗"),"✗"))
B29: 2026
B30: Jan 1 | E30: Balance b/d | P30: =IF(M30="","",IFERROR(IF(ABS(ABS(M30)-ABS('Mock B3 Ans'!M30))<0.5,"✓","✗"),"✗"))
B32: c) Show where the rent owing and the insurance prepaid appear. (2)
B33: Statement of Financial Position (extract) at 31 December 2025
E34: Particulars | R34: RM | W34: RM | AB34: RM
R35: Cost | W35: Accumulated Depreciation | AB35: Carrying Amount
E36: Current assets
E37: Other receivables (insurance prepaid) | AA37: =IF(W37="","",IFERROR(IF(ABS(ABS(W37)-ABS('Mock B3 Ans'!W37))<0.5,"✓","✗"),"✗"))
B38: Less: | E38: Current liabilities
E39: Other payables (rent owing) | AA39: =IF(W39="","",IFERROR(IF(ABS(ABS(W39)-ABS('Mock B3 Ans'!W39))<0.5,"✓","✗"),"✗"))

Sheet Mock B4
B1: Section B, Chapter 12: 10 marks
B2: Type your answers in the yellow cells. Numbers only: no RM, no commas. Enter 0 where the answer is nil. ✓ = correct, ✗ = try again.
B3: Your score: | H3: =COUNTIF(B4:AG26,"✓")&" correct out of 7 answer cells" -> 0 correct out of 7 answer cells
B6: a) Name the concept that applies to each situation. (4)
B7: Goods taken by the owner are recorded as drawings. | AC7: =IF(T7="","",IF(LOWER(TRIM(T7))=LOWER('Mock B4 Ans'!T7),"✓","✗"))
B8: A credit sale on 30 December is revenue of that year. | AC8: =IF(T8="","",IF(LOWER(TRIM(T8))=LOWER('Mock B4 Ans'!T8),"✓","✗"))
B9: The same inventory valuation method is used every year. | AC9: =IF(T9="","",IF(LOWER(TRIM(T9))=LOWER('Mock B4 Ans'!T9),"✓","✗"))
B10: Staff loyalty is not recorded in the accounts. | AC10: =IF(T10="","",IF(LOWER(TRIM(T10))=LOWER('Mock B4 Ans'!T10),"✓","✗"))
B12: b) Goods cost RM3,000. They can be sold for RM2,600 after repairs of RM400. Calculate the net realisable value and the value for inventory, and name the concept. (3)
B13: Figures from the question | X13: Figure
B14: Cost (RM) | X14: 3000
B15: Selling price (RM) | X15: 2600
B16: Repairs needed (RM) | X16: 400
B18: Net realisable value (RM) | AC18: =IF(X18="","",IFERROR(IF(ABS(ABS(X18)-ABS('Mock B4 Ans'!X18))<0.5,"✓","✗"),"✗"))
B19: Value for inventory (RM) | AC19: =IF(X19="","",IFERROR(IF(ABS(ABS(X19)-ABS('Mock B4 Ans'!X19))<0.5,"✓","✗"),"✗"))
B20: Concept | AC20: =IF(T20="","",IF(LOWER(TRIM(T20))=LOWER('Mock B4 Ans'!T20),"✓","✗"))
B22: c) Explain the going concern concept and how asset values would change if a business were closing. (3)

Sheet Mock C
B1: Section C, financial statements: 50 marks
B2: Type your answers in the yellow cells. Numbers only: no RM, no commas. Enter 0 where the answer is nil. ✓ = correct, ✗ = try again.
B3: Your score: | H3: =COUNTIF(B4:AG117,"✓")&" correct out of 61 answer cells" -> 0 correct out of 61 answer cells
B5: Siti Enterprise. Trial balance at 31 December 2025 and additional information.
B6: Siti Enterprise: Trial Balance at 31 December 2025
B7: Particulars | U7: Debit (RM) | AA7: Credit (RM)
B8: Revenue | AA8: 125000
B9: Purchases | U9: 68000
B10: Sales returns | U10: 2000
B11: Purchases returns | AA11: 1500
B12: Carriage inwards | U12: 1200
B13: Carriage outwards | U13: 800
B14: Inventory at 1 January 2025 | U14: 9000
B15: Wages | U15: 18000
B16: Rent | U16: 7700
B17: Insurance | U17: 2400
B18: Electricity | U18: 1900
B19: Discount allowed | U19: 500
B20: Discount received | AA20: 700
B21: Rent received | AA21: 3000
B22: Irrecoverable debts | U22: 600
B23: Premises at cost | U23: 80000
B24: Fixtures at cost | U24: 15000
B25: Provision for depreciation: fixtures | AA25: 3000
B26: Motor vehicle at cost | U26: 32000
B27: Provision for depreciation: motor vehicle | AA27: 12000
B28: Trade receivables | U28: 16200
B29: Allowance for irrecoverable debts | AA29: 700
B30: Trade payables | AA30: 9800
B31: Bank overdraft | AA31: 2100
B32: Cash | U32: 300
B33: Loan (repayable 2030) | AA33: 20000
B34: Capital | AA34: 89800
B35: Drawings | U35: 12000
B36: Total | U36: =SUM(U8:U35) -> 267600 | AA36: =SUM(AA8:AA35) -> 267600
B38: Additional information at 31 December 2025 | X38: Figure
B39: 1. Closing inventory (RM) | X39: 10500
B40: 2. Rent owing (RM) | X40: 700
B41: 3. Insurance prepaid (RM) | X41: 600
B42: 4. Rent received in advance (RM) | X42: 250
...

Sheet Mock A Ans
B1: Section A: multiple choice, 10 marks: Answers
B2: Answer sheet. Green cells hold the correct answers. Each figure is a formula linked to the question sheet, so the answers follow any change to the blue figures.
B3: Written answers are model answers: other wording that makes the same points also earns the marks.
B5: Section A: multiple choice. 1 mark each. Choose A, B, C or D.
B6: 1. Which double entry writes off an irrecoverable debt?
C7: A. Debit irrecoverable debts, credit trade receivable
C8: B. Debit trade receivable, credit irrecoverable debts
C9: C. Debit bank, credit irrecoverable debts
C10: D. Debit allowance for irrecoverable debts, credit bank
B11: Your answer | T11: ="A" -> A
B13: 2. Trade receivables are RM40,000. The allowance is to be 5%. The allowance brought forward is RM2,500. What is the effect on the Statement of Profit or Loss?
C14: A. Expense of RM2,000
C15: B. Income of RM500
C16: C. Expense of RM500
C17: D. Income of RM2,000
B18: Your answer | T18: ="B" -> B
B20: 3. A machine costs RM30,000, has a residual value of RM3,000 and a useful life of 6 years. What is the annual straight line depreciation?
C21: A. RM5,000
C22: B. RM3,000
C23: C. RM4,500
C24: D. RM5,500
B25: Your answer | T25: ="C" -> C
B27: 4. Equipment costs RM25,000 and is depreciated at 20% per year, reducing balance. What is the depreciation charge in Year 2?
C28: A. RM5,000
C29: B. RM3,200
C30: C. RM20,000
C31: D. RM4,000
B32: Your answer | T32: ="D" -> D
B34: 5. A vehicle cost RM20,000. Accumulated depreciation is RM12,000. It is sold for RM9,500. What is the result?
C35: A. Profit of RM1,500
C36: B. Loss of RM1,500
C37: C. Profit of RM9,500
C38: D. Loss of RM8,000
B39: Your answer | T39: ="A" -> A
B41: 6. Rent paid during the year was RM7,200. At the year end RM600 was owing. What is the rent expense?
C42: A. RM6,600
C43: B. RM7,200
C44: C. RM7,800
C45: D. RM8,400
B46: Your answer | T46: ="C" -> C
...

Sheet Mock B1 Ans
B1: Section B, Chapter 8: 10 marks: Answers
B2: Answer sheet. Green cells hold the correct answers. Each figure is a formula linked to the question sheet, so the answers follow any change to the blue figures.
B3: Written answers are model answers: other wording that makes the same points also earns the marks.
B5: Lim's year ends on 31 December 2025. Trade receivables are RM45,600 before writing off a debt of RM1,600 owed by Tan, who is bankrupt. The allowance for irrecoverable debts brought forward is RM1,500. It is to be 4% of the remaining trade receivables.
B6: Figures from the question | X6: Figure
B7: Trade receivables before writing off Tan (RM) | X7: ='Mock B1'!X7 -> 45600
B8: Tan's debt (RM) | X8: ='Mock B1'!X8 -> 1600
B9: Allowance brought forward (RM) | X9: ='Mock B1'!X9 -> 1500
B10: Allowance rate | X10: ='Mock B1'!X10 -> 0.04
B13: a) Calculate trade receivables after the write-off, the new allowance and the change in the allowance. (3)
B14: Trade receivables after the write-off (RM) | X14: =$X$7-$X$8 -> 44000
B15: New allowance (RM) | X15: =ROUND($X$14*$X$10,2) -> 1760
B16: Increase in the allowance (RM) | X16: =$X$15-$X$9 -> 260
B18: b) Prepare the journal entries to write off Tan's debt and to record the change in the allowance. (4)
B19: Date | E19: Particulars | U19: Debit | AA19: Credit
B20: 2025 | U20: RM | AA20: RM
B21: Dec 31 | E21: Irrecoverable debts | U21: =$X$8 -> 1600
E22: Tan | AA22: =$X$8 -> 1600
E23: (Being debt written off: customer bankrupt)
B24: Dec 31 | E24: Income statement | U24: =$X$16 -> 260
E25: Allowance for irrecoverable debts | AA25: =$X$16 -> 260
E26: (Being increase in the allowance)
B28: c) Show the Statement of Financial Position extract for trade receivables. (3)
B29: Statement of Financial Position (extract) at 31 December 2025
E30: Particulars | R30: RM | W30: RM | AB30: RM
R31: Cost | W31: Accumulated Depreciation | AB31: Carrying Amount
E32: Current assets
E33: Trade receivables | R33: =$X$14 -> 44000
B34: Less: | E34: Allowance for irrecoverable debts | R34: =-$X$15 -> -1760 | W34: =$X$14-$X$15 -> 42240

Sheet Mock B2 Ans
B1: Section B, Chapter 10: 10 marks: Answers
B2: Answer sheet. Green cells hold the correct answers. Each figure is a formula linked to the question sheet, so the answers follow any change to the blue figures.
B3: Written answers are model answers: other wording that makes the same points also earns the marks.
B5: On 1 January 2024 a business bought a van for RM48,000. It is depreciated at 25% per year, reducing balance. The year ends on 31 December. On 1 January 2026 the van was sold for RM25,000 by cheque.
B6: Figures from the question | X6: Figure
B7: Cost of van (RM) | X7: ='Mock B2'!X7 -> 48000
B8: Reducing balance rate | X8: ='Mock B2'!X8 -> 0.25
B9: Sale proceeds (RM) | X9: ='Mock B2'!X9 -> 25000
B12: a) Calculate the depreciation for 2024 and 2025 and the carrying amount at 31 December 2025. (3)
B13: Depreciation for 2024 (RM) | X13: =ROUND($X$7*$X$8,2) -> 12000
B14: Depreciation for 2025 (RM) | X14: =ROUND(($X$7-$X$13)*$X$8,2) -> 9000
B15: Carrying amount at 31 December 2025 (RM) | X15: =$X$7-$X$13-$X$14 -> 27000
B17: b) Prepare the Disposal of van account. (5)
B18: Dr | E18: Disposal of Van Account | AD18: Cr
B19: Date | E19: Particulars | L19: Folio | M19: Amount | R19: Date | U19: Particulars | AB19: Folio | AC19: Amount
B20: 2026 | M20: RM | R20: 2026 | AC20: RM
B21: Jan 1 | E21: Van | L21: GJ1 | M21: =$X$7 -> 48000 | R21: Jan 1 | U21: Provision for depreciation | AB21: GJ1 | AC21: =$X$13+$X$14 -> 21000
R22: Jan 1 | U22: Bank | AB22: CB1 | AC22: =$X$9 -> 25000
R23: Dec 31 | U23: Income statement (loss on disposal) | AB23: GJ2 | AC23: =$X$15-$X$9 -> 2000
M24: =SUM(M20:M23) -> 48000 | AC24: =SUM(AC20:AC23) -> 48000
B26: c) State where the loss appears, and name the concept that requires depreciation. (2)
B27: The loss on disposal is shown as | T27: ="Expense in the SPL" -> Expense in the SPL
B28: Concept that requires depreciation | T28: ="Accruals" -> Accruals

Sheet Mock B3 Ans
B1: Section B, Chapter 11: 10 marks: Answers
B2: Answer sheet. Green cells hold the correct answers. Each figure is a formula linked to the question sheet, so the answers follow any change to the blue figures.
B3: Written answers are model answers: other wording that makes the same points also earns the marks.
B5: Wong's year ends on 31 December 2025.
C6: • Rent is RM900 per month. RM9,900 was paid during the year.
C7: • Insurance of RM400 was prepaid at 1 January 2025. On 1 April 2025 RM3,000 was paid for 12 months.
B8: Figures from the question | X8: Figure
B9: Rent per month (RM) | X9: ='Mock B3'!X9 -> 900
B10: Rent paid in 2025 (RM) | X10: ='Mock B3'!X10 -> 9900
B11: Insurance prepaid at 1 January 2025 (RM) | X11: ='Mock B3'!X11 -> 400
B12: Insurance paid on 1 April 2025 (RM) | X12: ='Mock B3'!X12 -> 3000
B13: Months of that policy used in 2025 | X13: ='Mock B3'!X13 -> 9
B16: a) Calculate the rent expense, the rent owing, the insurance expense and the insurance prepaid. (4)
B17: Rent expense (RM) | X17: =12*$X$9 -> 10800
B18: Rent owing (RM) | X18: =12*$X$9-$X$10 -> 900
B19: Insurance expense (RM) | X19: =$X$11+$X$12*$X$13/12 -> 2650
B20: Insurance prepaid (RM) | X20: =$X$12*(12-$X$13)/12 -> 750
B22: b) Prepare the Insurance account for the year. (4)
B23: Dr | E23: Insurance Account | AD23: Cr
B24: Date | E24: Particulars | L24: Folio | M24: Amount | R24: Date | U24: Particulars | AB24: Folio | AC24: Amount
B25: 2025 | M25: RM | R25: 2025 | AC25: RM
B26: Jan 1 | E26: Balance b/d | M26: =$X$11 -> 400 | R26: Dec 31 | U26: Profit or loss | AB26: GJ1 | AC26: =$X$11+$X$12*$X$13/12 -> 2650
B27: Apr 1 | E27: Bank | L27: CB1 | M27: =$X$12 -> 3000 | R27: Dec 31 | U27: Balance c/d | AC27: =$X$12*(12-$X$13)/12 -> 750
M28: =SUM(M25:M27) -> 3400 | AC28: =SUM(AC25:AC27) -> 3400
B29: 2026
B30: Jan 1 | E30: Balance b/d | M30: =$X$12*(12-$X$13)/12 -> 750
B32: c) Show where the rent owing and the insurance prepaid appear. (2)
B33: Statement of Financial Position (extract) at 31 December 2025
E34: Particulars | R34: RM | W34: RM | AB34: RM
R35: Cost | W35: Accumulated Depreciation | AB35: Carrying Amount
E36: Current assets
E37: Other receivables (insurance prepaid) | W37: =$X$12*(12-$X$13)/12 -> 750
B38: Less: | E38: Current liabilities
E39: Other payables (rent owing) | W39: =12*$X$9-$X$10 -> 900

Sheet Mock B4 Ans
B1: Section B, Chapter 12: 10 marks: Answers
B2: Answer sheet. Green cells hold the correct answers. Each figure is a formula linked to the question sheet, so the answers follow any change to the blue figures.
B3: Written answers are model answers: other wording that makes the same points also earns the marks.
B6: a) Name the concept that applies to each situation. (4)
B7: Goods taken by the owner are recorded as drawings. | T7: ="Business entity" -> Business entity
B8: A credit sale on 30 December is revenue of that year. | T8: ="Realisation" -> Realisation
B9: The same inventory valuation method is used every year. | T9: ="Consistency" -> Consistency
B10: Staff loyalty is not recorded in the accounts. | T10: ="Money measurement" -> Money measurement
B12: b) Goods cost RM3,000. They can be sold for RM2,600 after repairs of RM400. Calculate the net realisable value and the value for inventory, and name the concept. (3)
B13: Figures from the question | X13: Figure
B14: Cost (RM) | X14: ='Mock B4'!X14 -> 3000
B15: Selling price (RM) | X15: ='Mock B4'!X15 -> 2600
B16: Repairs needed (RM) | X16: ='Mock B4'!X16 -> 400
B18: Net realisable value (RM) | X18: =$X$15-$X$16 -> 2200
B19: Value for inventory (RM) | X19: =MIN($X$14,$X$18) -> 2200
B20: Concept | T20: ="Prudence" -> Prudence
B22: c) Explain the going concern concept and how asset values would change if a business were closing. (3)
B23: Going concern assumes the business will continue trading for the foreseeable future, so assets are shown at cost less depreciation. If the business were closing, assets would be shown at what they would raise if sold now, which is often much lower.

Sheet Mock C Ans
B1: Section C, financial statements: 50 marks: Answers
B2: Answer sheet. Green cells hold the correct answers. Each figure is a formula linked to the question sheet, so the answers follow any change to the blue figures.
B3: Written answers are model answers: other wording that makes the same points also earns the marks.
B5: Siti Enterprise. Trial balance at 31 December 2025 and additional information.
B6: Siti Enterprise: Trial Balance at 31 December 2025
B7: Particulars | U7: Debit (RM) | AA7: Credit (RM)
B8: Revenue | AA8: ='Mock C'!AA8 -> 125000
B9: Purchases | U9: ='Mock C'!U9 -> 68000
B10: Sales returns | U10: ='Mock C'!U10 -> 2000
B11: Purchases returns | AA11: ='Mock C'!AA11 -> 1500
B12: Carriage inwards | U12: ='Mock C'!U12 -> 1200
B13: Carriage outwards | U13: ='Mock C'!U13 -> 800
B14: Inventory at 1 January 2025 | U14: ='Mock C'!U14 -> 9000
B15: Wages | U15: ='Mock C'!U15 -> 18000
B16: Rent | U16: ='Mock C'!U16 -> 7700
B17: Insurance | U17: ='Mock C'!U17 -> 2400
B18: Electricity | U18: ='Mock C'!U18 -> 1900
B19: Discount allowed | U19: ='Mock C'!U19 -> 500
B20: Discount received | AA20: ='Mock C'!AA20 -> 700
B21: Rent received | AA21: ='Mock C'!AA21 -> 3000
B22: Irrecoverable debts | U22: ='Mock C'!U22 -> 600
B23: Premises at cost | U23: ='Mock C'!U23 -> 80000
B24: Fixtures at cost | U24: ='Mock C'!U24 -> 15000
B25: Provision for depreciation: fixtures | AA25: ='Mock C'!AA25 -> 3000
B26: Motor vehicle at cost | U26: ='Mock C'!U26 -> 32000
B27: Provision for depreciation: motor vehicle | AA27: ='Mock C'!AA27 -> 12000
B28: Trade receivables | U28: ='Mock C'!U28 -> 16200
B29: Allowance for irrecoverable debts | AA29: ='Mock C'!AA29 -> 700
B30: Trade payables | AA30: ='Mock C'!AA30 -> 9800
B31: Bank overdraft | AA31: ='Mock C'!AA31 -> 2100
B32: Cash | U32: ='Mock C'!U32 -> 300
B33: Loan (repayable 2030) | AA33: ='Mock C'!AA33 -> 20000
B34: Capital | AA34: ='Mock C'!AA34 -> 89800
B35: Drawings | U35: ='Mock C'!U35 -> 12000
B36: Total | U36: =SUM(U8:U35) -> 267600 | AA36: =SUM(AA8:AA35) -> 267600
B38: Additional information at 31 December 2025 | X38: Figure
B39: 1. Closing inventory (RM) | X39: ='Mock C'!X39 -> 10500
B40: 2. Rent owing (RM) | X40: ='Mock C'!X40 -> 700
B41: 3. Insurance prepaid (RM) | X41: ='Mock C'!X41 -> 600
B42: 4. Rent received in advance (RM) | X42: ='Mock C'!X42 -> 250
...
