Workbook

Sheet Baca Saya
B1: Lejar dan Akaun Kawalan
B2: Prinsip Akaun. Percuma untuk digunakan dan dikongsi. Bukan untuk dijual.
B4: Cara menggunakan buku kerja ini
B5: 1. Baca nota dahulu. Kemudian buka tab Contoh (oren): tukar mana-mana angka biru dan lihat jawapan berubah.
B6: 2. Cuba tab soalan (biru). Taip jawapan dalam sel kuning.
B7: 3. Lajur kecil di sebelah setiap sel kuning menunjukkan ✓ (betul) atau ✗ (cuba lagi). Markah anda di bahagian atas.
B8: 4. Tarikh dan butir diberikan supaya helaian dapat menyemak angka anda. Cuba tulis akaun di atas kertas dahulu.
B9: 5. Tab Jawapan (hijau) menunjukkan jawapan penuh dalam format peperiksaan.
B11: Kunci warna
B12: 1000 | H12: Angka biru: maklumat soalan. Guru boleh menukarnya untuk membuat versi baharu.
B13: 1000 | H13: Angka hitam: formula. Jangan taip di atasnya.
H14: Sel kuning: taip jawapan anda di sini (nombor sahaja; 0 jika tiada).
B15: 1000 | H15: Sel hijau: jawapan yang betul (tab Jawapan).
B17: Helaian dalam buku kerja ini
B18: Helaian | I18: Kandungan
B19: Contoh AK | I19: Contoh (tab oren)
B20: Contoh Kontra | I20: Contoh (tab oren)
B21: S3 | I21: Soalan 3 (Kertas 2): Akaun Kawalan Belum Terima dan Belum Bayar [13 markah]. Jawapan: S3 Jawapan (tab hijau).
B22: S4 | I22: Soalan 4 (Kertas 2): Catatan kontra dan lejar bentuk berbaki [10 markah]. Jawapan: S4 Jawapan (tab hijau).
B23: S5 | I23: Latihan tambahan: sebelah dan sumber maklumat. Jawapan: S5 Jawapan (tab hijau).

Sheet Contoh AK
B1: Contoh AK
B2: Contoh. Tukar mana-mana angka biru dan semua jawapan di bawah akan dikemas kini.
B3: Angka hitam ialah formula. Jangan taip di atasnya.
B5: Contoh: Perniagaan Mesra, tahun berakhir 31 Disember 2025. Maklumat diambil daripada jurnal-jurnal dan Buku Tunai.
B6: Maklumat: Akaun Belum Terima | X6: Angka
B7: Akaun Belum Terima pada 1 Januari 2025 (RM) | X7: 12400
B8: Jualan kredit (RM) | X8: 48600
B9: Tunai dan cek diterima daripada pelanggan (RM) | X9: 41250
B10: Diskaun diberi (RM) | X10: 1150
B11: Pulangan jualan (RM) | X11: 860
B12: Hutang lapuk (RM) | X12: 540
B13: Cek pelanggan tak laku (RM) | X13: 700
B14: Kontra (RM) | X14: 380
B15: Faedah dikenakan atas akaun tertunggak (RM) | X15: 60
B17: Dt | E17: Akaun Kawalan Belum Terima | AD17: Kt
B18: Tarikh | E18: Butir | L18: Folio | M18: Amaun | R18: Tarikh | U18: Butir | AB18: Folio | AC18: Amaun
B19: 2025 | M19: RM | R19: 2025 | AC19: RM
B20: Jan 1 | E20: Baki b/b | M20: =$X$7 -> 12400 | R20: Dis 31 | U20: Bank | AB20: BT1 | AC20: =$X$9 -> 41250
B21: Dis 31 | E21: Jualan | L21: JJ1 | M21: =$X$8 -> 48600 | R21: Dis 31 | U21: Diskaun diberi | AB21: BT1 | AC21: =$X$10 -> 1150
B22: Dis 31 | E22: Bank (cek tak laku) | L22: BT1 | M22: =$X$13 -> 700 | R22: Dis 31 | U22: Pulangan jualan | AB22: JPJ1 | AC22: =$X$11 -> 860
B23: Dis 31 | E23: Faedah | L23: JA1 | M23: =$X$15 -> 60 | R23: Dis 31 | U23: Hutang lapuk | AB23: JA1 | AC23: =$X$12 -> 540
R24: Dis 31 | U24: Kontra | AB24: JA1 | AC24: =$X$14 -> 380
R25: Dis 31 | U25: Baki h/b | AC25: =$X$7+$X$8+$X$13+$X$15-($X$9+$X$10+$X$11+$X$12+$X$14) -> 17580
M26: =SUM(M19:M25) -> 61760 | AC26: =SUM(AC19:AC25) -> 61760
B27: 2026
B28: Jan 1 | E28: Baki b/b | M28: =$X$7+$X$8+$X$13+$X$15-($X$9+$X$10+$X$11+$X$12+$X$14) -> 17580
B30: Maklumat: Akaun Belum Bayar | X30: Angka
B31: Akaun Belum Bayar pada 1 Januari 2025 (RM) | X31: 9300
B32: Belian kredit (RM) | X32: 36800
B33: Cek dibayar kepada pembekal (RM) | X33: 34100
B34: Diskaun diterima (RM) | X34: 920
B35: Pulangan belian (RM) | X35: 640
B36: Kontra (RM) | X36: 380
B37: Angkutan masuk dikenakan oleh pembekal (RM) | X37: 150
B39: Dt | E39: Akaun Kawalan Belum Bayar | AD39: Kt
B40: Tarikh | E40: Butir | L40: Folio | M40: Amaun | R40: Tarikh | U40: Butir | AB40: Folio | AC40: Amaun
B41: 2025 | M41: RM | R41: 2025 | AC41: RM
B42: Dis 31 | E42: Bank | L42: BT1 | M42: =$X$33 -> 34100 | R42: Jan 1 | U42: Baki b/b | AC42: =$X$31 -> 9300
B43: Dis 31 | E43: Diskaun diterima | L43: BT1 | M43: =$X$34 -> 920 | R43: Dis 31 | U43: Belian | AB43: JB1 | AC43: =$X$32 -> 36800
B44: Dis 31 | E44: Pulangan belian | L44: JPB1 | M44: =$X$35 -> 640 | R44: Dis 31 | U44: Angkutan masuk | AB44: JA1 | AC44: =$X$37 -> 150
...

Sheet Contoh Kontra
B1: Contoh Kontra
B2: Contoh. Tukar mana-mana angka biru dan semua jawapan di bawah akan dikemas kini.
B3: Angka hitam ialah formula. Jangan taip di atasnya.
B5: Contoh catatan kontra: Pembekal Yani ialah pembekal dan juga pelanggan Perniagaan Wawan. Pada 3 Januari 2016, Perniagaan Wawan membeli barang niaga RM1 500 daripada Pembekal Yani. Pada 5 Januari 2016, Perniagaan Wawan menjual barang niaga RM450 kepada Pembekal Yani. Baki yang lebih kecil (RM450) dipindahkan ke baki yang lebih besar.
B6: Maklumat soalan | X6: Angka
B7: Belian daripada Pembekal Yani (RM) | X7: 1500
B8: Jualan kepada Pembekal Yani (RM) | X8: 450
B11: Lejar Belian
B12: Dt | E12: Akaun Belum Bayar: Pembekal Yani | AD12: Kt
B13: Tarikh | E13: Butir | L13: Folio | M13: Amaun | R13: Tarikh | U13: Butir | AB13: Folio | AC13: Amaun
B14: 2016 | M14: RM | R14: 2016 | AC14: RM
B15: Jan 31 | E15: Kontra | L15: JA1 | M15: =MIN($X$7,$X$8) -> 450 | R15: Jan 3 | U15: Belian | AB15: JB1 | AC15: =$X$7 -> 1500
B16: Jan 31 | E16: Baki h/b | M16: =$X$7-MIN($X$7,$X$8) -> 1050
M17: =SUM(M14:M16) -> 1500 | AC17: =SUM(AC14:AC16) -> 1500
R18: Feb 1 | U18: Baki b/b | AC18: =$X$7-MIN($X$7,$X$8) -> 1050
B20: Lejar Jualan
B21: Dt | E21: Akaun Belum Terima: Pembekal Yani | AD21: Kt
B22: Tarikh | E22: Butir | L22: Folio | M22: Amaun | R22: Tarikh | U22: Butir | AB22: Folio | AC22: Amaun
B23: 2016 | M23: RM | R23: 2016 | AC23: RM
B24: Jan 5 | E24: Jualan | L24: JJ1 | M24: =$X$8 -> 450 | R24: Jan 31 | U24: Kontra | AB24: JA1 | AC24: =MIN($X$7,$X$8) -> 450
M25: =SUM(M23:M24) -> 450 | AC25: =SUM(AC23:AC24) -> 450

Sheet S3
B1: Soalan 3 (Kertas 2): Akaun Kawalan Belum Terima dan Belum Bayar [13 markah]
B2: Taip jawapan anda dalam sel kuning. Nombor sahaja: tanpa RM, tanpa koma. Masukkan 0 jika tiada jawapan. Gunakan tanda tolak (-) untuk pengurangan. ✓ = betul, ✗ = cuba lagi.
B3: Markah anda: | H3: =COUNTIF(B4:AG54,"✓")&" betul daripada 25 sel jawapan" -> 0 betul daripada 25 sel jawapan
B5: Encik Nizam ialah pemilik Kedai Alatulis Nizam. Maklumat berikut diperoleh daripada buku perniagaannya bagi tahun berakhir 30 Jun 2025.
B6: Maklumat soalan | X6: Angka
B7: Baki
B8: Akaun Belum Terima pada 1 Julai 2024 (RM) | X8: 15200
B9: Akaun Belum Terima pada 30 Jun 2025 (RM) | X9: 18450
B10: Akaun Belum Bayar pada 1 Julai 2024 (RM) | X10: 9800
B11: Akaun Belum Bayar pada 30 Jun 2025 (RM) | X11: 11250
B12: Ringkasan Akaun Bank
B13: Diterima daripada Akaun Belum Terima (RM) | X13: 72300
B14: Dibayar kepada Akaun Belum Bayar (RM) | X14: 54600
B15: Maklumat tambahan
B16: Diskaun diberi (RM) | X16: 2100
B17: Diskaun diterima (RM) | X17: 1350
B18: Pulangan jualan (RM) | X18: 950
B19: Pulangan belian (RM) | X19: 720
B20: Hutang lapuk dihapuskan (RM) | X20: 800
B21: Cek pelanggan tak laku (RM) | X21: 1200
B22: Kontra antara Lejar Jualan dan Lejar Belian (RM) | X22: 600
B23: Angkutan masuk dikenakan oleh pembekal (RM) | X23: 300
B26: (a) Hitung jualan kredit dan belian kredit bagi tahun berakhir 30 Jun 2025. [2 markah]
B27: Jualan kredit (RM) | AC27: =IF(X27="","",IFERROR(IF(ABS(ABS(X27)-ABS('S3 Jawapan'!X27))<0.5,"✓","✗"),"✗"))
B28: Belian kredit (RM) | AC28: =IF(X28="","",IFERROR(IF(ABS(ABS(X28)-ABS('S3 Jawapan'!X28))<0.5,"✓","✗"),"✗"))
B30: (b) Sediakan Akaun Kawalan Belum Terima bagi tahun berakhir 30 Jun 2025. [6 markah]
B31: Dt | E31: Akaun Kawalan Belum Terima | AD31: Kt
B32: Tarikh | E32: Butir | L32: Folio | M32: Amaun | R32: Tarikh | U32: Butir | AB32: Folio | AC32: Amaun
B33: 2024 | M33: RM | R33: 2025 | AC33: RM
B34: Jul 1 | E34: Baki b/b | P34: =IF(M34="","",IFERROR(IF(ABS(ABS(M34)-ABS('S3 Jawapan'!M34))<0.5,"✓","✗"),"✗")) | R34: Jun 30 | U34: Bank | AB34: BT1 | AF34: =IF(AC34="","",IFERROR(IF(ABS(ABS(AC34)-ABS('S3 Jawapan'!AC34))<0.5,"✓","✗"),"✗"))
B35: 2025 | R35: Jun 30 | U35: Diskaun diberi | AB35: BT1 | AF35: =IF(AC35="","",IFERROR(IF(ABS(ABS(AC35)-ABS('S3 Jawapan'!AC35))<0.5,"✓","✗"),"✗"))
B36: Jun 30 | E36: Jualan | L36: JJ1 | P36: =IF(M36="","",IFERROR(IF(ABS(ABS(M36)-ABS('S3 Jawapan'!M36))<0.5,"✓","✗"),"✗")) | R36: Jun 30 | U36: Pulangan jualan | AB36: JPJ1 | AF36: =IF(AC36="","",IFERROR(IF(ABS(ABS(AC36)-ABS('S3 Jawapan'!AC36))<0.5,"✓","✗"),"✗"))
B37: Jun 30 | E37: Bank (cek tak laku) | L37: BT1 | P37: =IF(M37="","",IFERROR(IF(ABS(ABS(M37)-ABS('S3 Jawapan'!M37))<0.5,"✓","✗"),"✗")) | R37: Jun 30 | U37: Hutang lapuk | AB37: JA1 | AF37: =IF(AC37="","",IFERROR(IF(ABS(ABS(AC37)-ABS('S3 Jawapan'!AC37))<0.5,"✓","✗"),"✗"))
R38: Jun 30 | U38: Kontra | AB38: JA1 | AF38: =IF(AC38="","",IFERROR(IF(ABS(ABS(AC38)-ABS('S3 Jawapan'!AC38))<0.5,"✓","✗"),"✗"))
R39: Jun 30 | U39: Baki h/b | AF39: =IF(AC39="","",IFERROR(IF(ABS(ABS(AC39)-ABS('S3 Jawapan'!AC39))<0.5,"✓","✗"),"✗"))
P40: =IF(M40="","",IFERROR(IF(ABS(ABS(M40)-ABS('S3 Jawapan'!M40))<0.5,"✓","✗"),"✗")) | AF40: =IF(AC40="","",IFERROR(IF(ABS(ABS(AC40)-ABS('S3 Jawapan'!AC40))<0.5,"✓","✗"),"✗"))
B41: Jul 1 | E41: Baki b/b | P41: =IF(M41="","",IFERROR(IF(ABS(ABS(M41)-ABS('S3 Jawapan'!M41))<0.5,"✓","✗"),"✗"))
B43: (c) Sediakan Akaun Kawalan Belum Bayar bagi tahun berakhir 30 Jun 2025. [5 markah]
B44: Dt | E44: Akaun Kawalan Belum Bayar | AD44: Kt
B45: Tarikh | E45: Butir | L45: Folio | M45: Amaun | R45: Tarikh | U45: Butir | AB45: Folio | AC45: Amaun
...

Sheet S4
B1: Soalan 4 (Kertas 2): Catatan kontra dan lejar bentuk berbaki [10 markah]
B2: Taip jawapan anda dalam sel kuning. Nombor sahaja: tanpa RM, tanpa koma. Masukkan 0 jika tiada jawapan. Gunakan tanda tolak (-) untuk pengurangan. ✓ = betul, ✗ = cuba lagi.
B3: Markah anda: | H3: =COUNTIF(B4:AG43,"✓")&" betul daripada 14 sel jawapan" -> 0 betul daripada 14 sel jawapan
B5: Kedai Lina ialah pelanggan dan juga pembekal kepada Perniagaan Danial. Urus niaga berikut berlaku pada bulan Januari 2025.
C6: • 1 Januari: Kedai Lina berhutang RM2 000 kepada Perniagaan Danial.
C7: • 6 Januari: Menjual barang niaga secara kredit kepada Kedai Lina RM1 800.
C8: • 12 Januari: Kedai Lina memulangkan barang niaga RM200.
C9: • 15 Januari: Membeli barang niaga secara kredit daripada Kedai Lina RM900.
C10: • 20 Januari: Menerima cek RM1 500 daripada Kedai Lina.
C11: • 31 Januari: Baki dalam Lejar Belian dipindahkan ke Lejar Jualan (kontra).
B12: Maklumat soalan | X12: Angka
B13: Baki pada 1 Januari (RM) | X13: 2000
B14: Jualan kredit (RM) | X14: 1800
B15: Pulangan jualan (RM) | X15: 200
B16: Belian kredit (RM) | X16: 900
B17: Cek diterima (RM) | X17: 1500
B20: (a) Sediakan Akaun Belum Terima Kedai Lina dalam Lejar Jualan dalam bentuk berbaki. [5 markah]
B21: Tarikh dan butir (2025) | L21: Debit (RM) | S21: Kredit (RM) | Z21: Baki (RM)
B22: Jan 1 Baki b/b | AF22: =IF(Z22="","",IFERROR(IF(ABS(ABS(Z22)-ABS('S4 Jawapan'!Z22))<0.5,"✓","✗"),"✗"))
B23: Jan 6 Jualan | R23: =IF(L23="","",IFERROR(IF(ABS(ABS(L23)-ABS('S4 Jawapan'!L23))<0.5,"✓","✗"),"✗")) | AF23: =IF(Z23="","",IFERROR(IF(ABS(ABS(Z23)-ABS('S4 Jawapan'!Z23))<0.5,"✓","✗"),"✗"))
B24: Jan 12 Pulangan jualan | Y24: =IF(S24="","",IFERROR(IF(ABS(ABS(S24)-ABS('S4 Jawapan'!S24))<0.5,"✓","✗"),"✗")) | AF24: =IF(Z24="","",IFERROR(IF(ABS(ABS(Z24)-ABS('S4 Jawapan'!Z24))<0.5,"✓","✗"),"✗"))
B25: Jan 20 Bank | Y25: =IF(S25="","",IFERROR(IF(ABS(ABS(S25)-ABS('S4 Jawapan'!S25))<0.5,"✓","✗"),"✗")) | AF25: =IF(Z25="","",IFERROR(IF(ABS(ABS(Z25)-ABS('S4 Jawapan'!Z25))<0.5,"✓","✗"),"✗"))
B26: Jan 31 Kontra | Y26: =IF(S26="","",IFERROR(IF(ABS(ABS(S26)-ABS('S4 Jawapan'!S26))<0.5,"✓","✗"),"✗")) | AF26: =IF(Z26="","",IFERROR(IF(ABS(ABS(Z26)-ABS('S4 Jawapan'!Z26))<0.5,"✓","✗"),"✗"))
B28: (b) Sediakan Akaun Belum Bayar Kedai Lina dalam Lejar Belian. [2 markah]
B29: Dt | E29: Akaun Belum Bayar: Kedai Lina | AD29: Kt
B30: Tarikh | E30: Butir | L30: Folio | M30: Amaun | R30: Tarikh | U30: Butir | AB30: Folio | AC30: Amaun
B31: 2025 | M31: RM | R31: 2025 | AC31: RM
B32: Jan 31 | E32: Kontra | L32: JA1 | P32: =IF(M32="","",IFERROR(IF(ABS(ABS(M32)-ABS('S4 Jawapan'!M32))<0.5,"✓","✗"),"✗")) | R32: Jan 15 | U32: Belian | AB32: JB1 | AF32: =IF(AC32="","",IFERROR(IF(ABS(ABS(AC32)-ABS('S4 Jawapan'!AC32))<0.5,"✓","✗"),"✗"))
P33: =IF(M33="","",IFERROR(IF(ABS(ABS(M33)-ABS('S4 Jawapan'!M33))<0.5,"✓","✗"),"✗")) | AF33: =IF(AC33="","",IFERROR(IF(ABS(ABS(AC33)-ABS('S4 Jawapan'!AC33))<0.5,"✓","✗"),"✗"))
B35: (c) Di sebelah manakah catatan kontra direkodkan dalam Akaun Kawalan Belum Terima? [1 markah]
B36: Sebelah | AC36: =IF(T36="","",IF(LOWER(TRIM(T36))=LOWER('S4 Jawapan'!T36),"✓","✗"))
B38: (d) Nyatakan dua implikasi Akaun Kawalan. [2 markah]

Sheet S5
B1: Latihan tambahan: sebelah dan sumber maklumat
B2: Taip jawapan anda dalam sel kuning. Nombor sahaja: tanpa RM, tanpa koma. Masukkan 0 jika tiada jawapan. Gunakan tanda tolak (-) untuk pengurangan. ✓ = betul, ✗ = cuba lagi.
B3: Markah anda: | H3: =COUNTIF(B4:AG26,"✓")&" betul daripada 20 sel jawapan" -> 0 betul daripada 20 sel jawapan
B5: Bagi setiap item, pilih sebelah yang betul dalam Akaun Kawalan Belum Terima (AKBT) atau Akaun Kawalan Belum Bayar (AKBB), dan sumber maklumatnya.
B6: 1. Jualan kredit: sebelah | AC6: =IF(T6="","",IF(LOWER(TRIM(T6))=LOWER('S5 Jawapan'!T6),"✓","✗"))
B7: 1. Jualan kredit: sumber maklumat | AC7: =IF(T7="","",IF(LOWER(TRIM(T7))=LOWER('S5 Jawapan'!T7),"✓","✗"))
B8: 2. Belian kredit: sebelah | AC8: =IF(T8="","",IF(LOWER(TRIM(T8))=LOWER('S5 Jawapan'!T8),"✓","✗"))
B9: 2. Belian kredit: sumber maklumat | AC9: =IF(T9="","",IF(LOWER(TRIM(T9))=LOWER('S5 Jawapan'!T9),"✓","✗"))
B10: 3. Pulangan jualan: sebelah | AC10: =IF(T10="","",IF(LOWER(TRIM(T10))=LOWER('S5 Jawapan'!T10),"✓","✗"))
B11: 3. Pulangan jualan: sumber maklumat | AC11: =IF(T11="","",IF(LOWER(TRIM(T11))=LOWER('S5 Jawapan'!T11),"✓","✗"))
B12: 4. Pulangan belian: sebelah | AC12: =IF(T12="","",IF(LOWER(TRIM(T12))=LOWER('S5 Jawapan'!T12),"✓","✗"))
B13: 4. Pulangan belian: sumber maklumat | AC13: =IF(T13="","",IF(LOWER(TRIM(T13))=LOWER('S5 Jawapan'!T13),"✓","✗"))
B14: 5. Cek diterima daripada pelanggan: sebelah | AC14: =IF(T14="","",IF(LOWER(TRIM(T14))=LOWER('S5 Jawapan'!T14),"✓","✗"))
B15: 5. Cek diterima daripada pelanggan: sumber maklumat | AC15: =IF(T15="","",IF(LOWER(TRIM(T15))=LOWER('S5 Jawapan'!T15),"✓","✗"))
B16: 6. Diskaun diterima: sebelah | AC16: =IF(T16="","",IF(LOWER(TRIM(T16))=LOWER('S5 Jawapan'!T16),"✓","✗"))
B17: 6. Diskaun diterima: sumber maklumat | AC17: =IF(T17="","",IF(LOWER(TRIM(T17))=LOWER('S5 Jawapan'!T17),"✓","✗"))
... B25: 10. Faedah dikenakan oleh pembekal: sumber maklumat | AC25: =IF(T25="","",IF(LOWER(TRIM(T25))=LOWER('S5 Jawapan'!T25),"✓","✗"))

Sheet S3 Jawapan
B1: Soalan 3 (Kertas 2): Akaun Kawalan Belum Terima dan Belum Bayar [13 markah]: Jawapan
B2: Helaian jawapan. Sel hijau mengandungi jawapan yang betul. Setiap angka ialah formula yang dipautkan kepada helaian soalan.
B3: Jawapan bertulis ialah jawapan contoh: perkataan lain yang membawa maksud yang sama juga diterima.
B5: Encik Nizam ialah pemilik Kedai Alatulis Nizam. Maklumat berikut diperoleh daripada buku perniagaannya bagi tahun berakhir 30 Jun 2025.
B6: Maklumat soalan | X6: Angka
B7: Baki
B8: Akaun Belum Terima pada 1 Julai 2024 (RM) | X8: =S3!X8 -> 15200
B9: Akaun Belum Terima pada 30 Jun 2025 (RM) | X9: =S3!X9 -> 18450
B10: Akaun Belum Bayar pada 1 Julai 2024 (RM) | X10: =S3!X10 -> 9800
B11: Akaun Belum Bayar pada 30 Jun 2025 (RM) | X11: =S3!X11 -> 11250
B12: Ringkasan Akaun Bank
B13: Diterima daripada Akaun Belum Terima (RM) | X13: =S3!X13 -> 72300
B14: Dibayar kepada Akaun Belum Bayar (RM) | X14: =S3!X14 -> 54600
B15: Maklumat tambahan
B16: Diskaun diberi (RM) | X16: =S3!X16 -> 2100
B17: Diskaun diterima (RM) | X17: =S3!X17 -> 1350
B18: Pulangan jualan (RM) | X18: =S3!X18 -> 950
B19: Pulangan belian (RM) | X19: =S3!X19 -> 720
B20: Hutang lapuk dihapuskan (RM) | X20: =S3!X20 -> 800
B21: Cek pelanggan tak laku (RM) | X21: =S3!X21 -> 1200
B22: Kontra antara Lejar Jualan dan Lejar Belian (RM) | X22: =S3!X22 -> 600
B23: Angkutan masuk dikenakan oleh pembekal (RM) | X23: =S3!X23 -> 300
B26: (a) Hitung jualan kredit dan belian kredit bagi tahun berakhir 30 Jun 2025. [2 markah]
B27: Jualan kredit (RM) | X27: =$X$9+$X$13+$X$16+$X$18+$X$20+$X$22-$X$8-$X$21 -> 78800
B28: Belian kredit (RM) | X28: =$X$11+$X$14+$X$17+$X$19+$X$22-$X$10-$X$23 -> 58420
B30: (b) Sediakan Akaun Kawalan Belum Terima bagi tahun berakhir 30 Jun 2025. [6 markah]
B31: Dt | E31: Akaun Kawalan Belum Terima | AD31: Kt
B32: Tarikh | E32: Butir | L32: Folio | M32: Amaun | R32: Tarikh | U32: Butir | AB32: Folio | AC32: Amaun
B33: 2024 | M33: RM | R33: 2025 | AC33: RM
B34: Jul 1 | E34: Baki b/b | M34: =$X$8 -> 15200 | R34: Jun 30 | U34: Bank | AB34: BT1 | AC34: =$X$13 -> 72300
B35: 2025 | R35: Jun 30 | U35: Diskaun diberi | AB35: BT1 | AC35: =$X$16 -> 2100
B36: Jun 30 | E36: Jualan | L36: JJ1 | M36: =$X$27 -> 78800 | R36: Jun 30 | U36: Pulangan jualan | AB36: JPJ1 | AC36: =$X$18 -> 950
B37: Jun 30 | E37: Bank (cek tak laku) | L37: BT1 | M37: =$X$21 -> 1200 | R37: Jun 30 | U37: Hutang lapuk | AB37: JA1 | AC37: =$X$20 -> 800
R38: Jun 30 | U38: Kontra | AB38: JA1 | AC38: =$X$22 -> 600
R39: Jun 30 | U39: Baki h/b | AC39: =$X$9 -> 18450
M40: =SUM(M33:M39) -> 95200 | AC40: =SUM(AC33:AC39) -> 95200
B41: Jul 1 | E41: Baki b/b | M41: =$X$9 -> 18450
B43: (c) Sediakan Akaun Kawalan Belum Bayar bagi tahun berakhir 30 Jun 2025. [5 markah]
B44: Dt | E44: Akaun Kawalan Belum Bayar | AD44: Kt
B45: Tarikh | E45: Butir | L45: Folio | M45: Amaun | R45: Tarikh | U45: Butir | AB45: Folio | AC45: Amaun
...

Sheet S4 Jawapan
B1: Soalan 4 (Kertas 2): Catatan kontra dan lejar bentuk berbaki [10 markah]: Jawapan
B2: Helaian jawapan. Sel hijau mengandungi jawapan yang betul. Setiap angka ialah formula yang dipautkan kepada helaian soalan.
B3: Jawapan bertulis ialah jawapan contoh: perkataan lain yang membawa maksud yang sama juga diterima.
B5: Kedai Lina ialah pelanggan dan juga pembekal kepada Perniagaan Danial. Urus niaga berikut berlaku pada bulan Januari 2025.
C6: • 1 Januari: Kedai Lina berhutang RM2 000 kepada Perniagaan Danial.
C7: • 6 Januari: Menjual barang niaga secara kredit kepada Kedai Lina RM1 800.
C8: • 12 Januari: Kedai Lina memulangkan barang niaga RM200.
C9: • 15 Januari: Membeli barang niaga secara kredit daripada Kedai Lina RM900.
C10: • 20 Januari: Menerima cek RM1 500 daripada Kedai Lina.
C11: • 31 Januari: Baki dalam Lejar Belian dipindahkan ke Lejar Jualan (kontra).
B12: Maklumat soalan | X12: Angka
B13: Baki pada 1 Januari (RM) | X13: =S4!X13 -> 2000
B14: Jualan kredit (RM) | X14: =S4!X14 -> 1800
B15: Pulangan jualan (RM) | X15: =S4!X15 -> 200
B16: Belian kredit (RM) | X16: =S4!X16 -> 900
B17: Cek diterima (RM) | X17: =S4!X17 -> 1500
B20: (a) Sediakan Akaun Belum Terima Kedai Lina dalam Lejar Jualan dalam bentuk berbaki. [5 markah]
B21: Tarikh dan butir (2025) | L21: Debit (RM) | S21: Kredit (RM) | Z21: Baki (RM)
B22: Jan 1 Baki b/b | Z22: =$X$13 -> 2000
B23: Jan 6 Jualan | L23: =$X$14 -> 1800 | Z23: =$Z$22+$X$14 -> 3800
B24: Jan 12 Pulangan jualan | S24: =$X$15 -> 200 | Z24: =$Z$23-$X$15 -> 3600
B25: Jan 20 Bank | S25: =$X$17 -> 1500 | Z25: =$Z$24-$X$17 -> 2100
B26: Jan 31 Kontra | S26: =MIN($X$16,$X$13+$X$14-$X$15-$X$17) -> 900 | Z26: =$Z$25-MIN($X$16,$X$13+$X$14-$X$15-$X$17) -> 1200
B28: (b) Sediakan Akaun Belum Bayar Kedai Lina dalam Lejar Belian. [2 markah]
B29: Dt | E29: Akaun Belum Bayar: Kedai Lina | AD29: Kt
B30: Tarikh | E30: Butir | L30: Folio | M30: Amaun | R30: Tarikh | U30: Butir | AB30: Folio | AC30: Amaun
B31: 2025 | M31: RM | R31: 2025 | AC31: RM
B32: Jan 31 | E32: Kontra | L32: JA1 | M32: =MIN($X$16,$X$13+$X$14-$X$15-$X$17) -> 900 | R32: Jan 15 | U32: Belian | AB32: JB1 | AC32: =$X$16 -> 900
M33: =SUM(M31:M32) -> 900 | AC33: =SUM(AC31:AC32) -> 900
B35: (c) Di sebelah manakah catatan kontra direkodkan dalam Akaun Kawalan Belum Terima? [1 markah]
B36: Sebelah | T36: ="Kredit" -> Kredit
B38: (d) Nyatakan dua implikasi Akaun Kawalan. [2 markah]
B39: Mana-mana dua: Sukar mengesan kesilapan ketinggalan catatan. Sukar mengesan kesilapan menjumlahkan Akaun Belum Terima dan Akaun Belum Bayar. Sukar mengesan kesilapan memindahkan catatan.

Sheet S5 Jawapan
B1: Latihan tambahan: sebelah dan sumber maklumat: Jawapan
B2: Helaian jawapan. Sel hijau mengandungi jawapan yang betul. Setiap angka ialah formula yang dipautkan kepada helaian soalan.
B3: Jawapan bertulis ialah jawapan contoh: perkataan lain yang membawa maksud yang sama juga diterima.
B5: Bagi setiap item, pilih sebelah yang betul dalam Akaun Kawalan Belum Terima (AKBT) atau Akaun Kawalan Belum Bayar (AKBB), dan sumber maklumatnya.
B6: 1. Jualan kredit: sebelah | T6: ="Debit AKBT" -> Debit AKBT
B7: 1. Jualan kredit: sumber maklumat | T7: ="Jurnal Jualan" -> Jurnal Jualan
B8: 2. Belian kredit: sebelah | T8: ="Kredit AKBB" -> Kredit AKBB
B9: 2. Belian kredit: sumber maklumat | T9: ="Jurnal Belian" -> Jurnal Belian
B10: 3. Pulangan jualan: sebelah | T10: ="Kredit AKBT" -> Kredit AKBT
B11: 3. Pulangan jualan: sumber maklumat | T11: ="Jurnal Pulangan Jualan" -> Jurnal Pulangan Jualan
B12: 4. Pulangan belian: sebelah | T12: ="Debit AKBB" -> Debit AKBB
B13: 4. Pulangan belian: sumber maklumat | T13: ="Jurnal Pulangan Belian" -> Jurnal Pulangan Belian
B14: 5. Cek diterima daripada pelanggan: sebelah | T14: ="Kredit AKBT" -> Kredit AKBT
B15: 5. Cek diterima daripada pelanggan: sumber maklumat | T15: ="Buku Tunai" -> Buku Tunai
B16: 6. Diskaun diterima: sebelah | T16: ="Debit AKBB" -> Debit AKBB
B17: 6. Diskaun diterima: sumber maklumat | T17: ="Buku Tunai" -> Buku Tunai
B18: 7. Hutang lapuk dihapuskan: sebelah | T18: ="Kredit AKBT" -> Kredit AKBT
B19: 7. Hutang lapuk dihapuskan: sumber maklumat | T19: ="Jurnal Am" -> Jurnal Am
B20: 8. Cek pelanggan tak laku: sebelah | T20: ="Debit AKBT" -> Debit AKBT
B21: 8. Cek pelanggan tak laku: sumber maklumat | T21: ="Buku Tunai" -> Buku Tunai
B22: 9. Kontra (dalam Akaun Kawalan Belum Bayar): sebelah | T22: ="Debit AKBB" -> Debit AKBB
B23: 9. Kontra (dalam Akaun Kawalan Belum Bayar): sumber maklumat | T23: ="Jurnal Am" -> Jurnal Am
B24: 10. Faedah dikenakan oleh pembekal: sebelah | T24: ="Kredit AKBB" -> Kredit AKBB
B25: 10. Faedah dikenakan oleh pembekal: sumber maklumat | T25: ="Jurnal Am" -> Jurnal Am
