Workbook

Sheet Baca Saya
B1: Kertas 1: Soalan Objektif
B2: Prinsip Akaun. Percuma untuk digunakan dan dikongsi. Bukan untuk dijual.
B4: Cara menggunakan buku kerja ini
B5: 1. Baca nota dahulu. Kemudian buka tab Contoh (oren): tukar mana-mana angka biru dan lihat jawapan berubah.
B6: 2. Cuba tab soalan (biru). Taip jawapan dalam sel kuning.
B7: 3. Lajur kecil di sebelah setiap sel kuning menunjukkan ✓ (betul) atau ✗ (cuba lagi). Markah anda di bahagian atas.
B8: 4. Tarikh dan butir diberikan supaya helaian dapat menyemak angka anda. Cuba tulis akaun di atas kertas dahulu.
B9: 5. Tab Jawapan (hijau) menunjukkan jawapan penuh dalam format peperiksaan.
B11: Kunci warna
B12: 1000 | H12: Angka biru: maklumat soalan. Guru boleh menukarnya untuk membuat versi baharu.
B13: 1000 | H13: Angka hitam: formula. Jangan taip di atasnya.
H14: Sel kuning: taip jawapan anda di sini (nombor sahaja; 0 jika tiada).
B15: 1000 | H15: Sel hijau: jawapan yang betul (tab Jawapan).
B17: Helaian dalam buku kerja ini
B18: Helaian | I18: Kandungan
B19: K1 | I19: Kertas 1: 15 soalan objektif [15 markah]. Jawapan: K1 Jawapan (tab hijau).

Sheet K1
B1: Kertas 1: 15 soalan objektif [15 markah]
B2: Taip jawapan anda dalam sel kuning. Nombor sahaja: tanpa RM, tanpa koma. Masukkan 0 jika tiada jawapan. Gunakan tanda tolak (-) untuk pengurangan. ✓ = betul, ✗ = cuba lagi.
B3: Markah anda: | H3: =COUNTIF(B4:AG110,"✓")&" betul daripada 15 sel jawapan" -> 0 betul daripada 15 sel jawapan
B5: Kertas 1: soalan objektif. Setiap soalan diikuti oleh empat pilihan jawapan A, B, C dan D. Pilih satu jawapan sahaja. [15 markah]
B6: 1. Encik Amri memulakan perniagaan dengan memasukkan RM30 000 ke dalam akaun bank perniagaan. Apakah kesan urus niaga ini?
C7: A. Aset bertambah RM30 000; ekuiti pemilik bertambah RM30 000
C8: B. Aset bertambah RM30 000; liabiliti bertambah RM30 000
C9: C. Aset berkurang RM30 000; ekuiti pemilik bertambah RM30 000
C10: D. Liabiliti bertambah RM30 000; ekuiti pemilik berkurang RM30 000
B11: Jawapan anda | AC11: =IF(T11="","",IF(LOWER(TRIM(T11))=LOWER('K1 Jawapan'!T11),"✓","✗"))
B13: 2. Kedai Nora membayar hutang kepada pembekal dengan cek RM2 400 dan menerima diskaun tunai RM100. Apakah kesan urus niaga ini ke atas aset, liabiliti dan ekuiti pemilik?
C14: A. Aset berkurang RM2 500; liabiliti berkurang RM2 400; ekuiti pemilik berkurang RM100
C15: B. Aset berkurang RM2 400; liabiliti berkurang RM2 500; ekuiti pemilik bertambah RM100
C16: C. Aset bertambah RM2 400; liabiliti berkurang RM2 500; ekuiti pemilik bertambah RM100
C17: D. Aset berkurang RM2 400; liabiliti berkurang RM2 400; tiada kesan ke atas ekuiti pemilik
B18: Jawapan anda | AC18: =IF(T18="","",IF(LOWER(TRIM(T18))=LOWER('K1 Jawapan'!T18),"✓","✗"))
B20: 3. Jumlah aset sebuah perniagaan ialah RM85 000 dan jumlah liabilitinya RM23 000. Berapakah ekuiti pemilik?
C21: A. RM23 000
C22: B. RM108 000
C23: C. RM62 000
C24: D. RM85 000
B25: Jawapan anda | AC25: =IF(T25="","",IF(LOWER(TRIM(T25))=LOWER('K1 Jawapan'!T25),"✓","✗"))
B27: 4. Modal awal Perniagaan Seri ialah RM40 000. Untung bersih tahun itu RM12 000 dan ambilan RM5 000. Berapakah ekuiti pemilik pada akhir tahun?
C28: A. RM57 000
C29: B. RM52 000
C30: C. RM35 000
C31: D. RM47 000
B32: Jawapan anda | AC32: =IF(T32="","",IF(LOWER(TRIM(T32))=LOWER('K1 Jawapan'!T32),"✓","✗"))
B34: 5. Urus niaga manakah yang tidak mengubah jumlah aset?
C35: A. Membeli perabot dengan cek
C36: B. Membayar sewa secara tunai
C37: C. Menerima pinjaman bank
C38: D. Pemilik mengambil tunai untuk kegunaan sendiri
B39: Jawapan anda | AC39: =IF(T39="","",IF(LOWER(TRIM(T39))=LOWER('K1 Jawapan'!T39),"✓","✗"))
B41: 6. Barang niaga berkos RM1 500 dijual secara kredit dengan harga RM2 100. Apakah kesan urus niaga ini?
C42: A. Aset bertambah RM2 100; ekuiti pemilik bertambah RM2 100
C43: B. Aset bertambah RM600; ekuiti pemilik bertambah RM600
C44: C. Aset berkurang RM1 500; liabiliti bertambah RM2 100
C45: D. Aset bertambah RM600; liabiliti bertambah RM600
B46: Jawapan anda | AC46: =IF(T46="","",IF(LOWER(TRIM(T46))=LOWER('K1 Jawapan'!T46),"✓","✗"))
...

Sheet K1 Jawapan
B1: Kertas 1: 15 soalan objektif [15 markah]: Jawapan
B2: Helaian jawapan. Sel hijau mengandungi jawapan yang betul. Setiap angka ialah formula yang dipautkan kepada helaian soalan.
B3: Jawapan bertulis ialah jawapan contoh: perkataan lain yang membawa maksud yang sama juga diterima.
B5: Kertas 1: soalan objektif. Setiap soalan diikuti oleh empat pilihan jawapan A, B, C dan D. Pilih satu jawapan sahaja. [15 markah]
B6: 1. Encik Amri memulakan perniagaan dengan memasukkan RM30 000 ke dalam akaun bank perniagaan. Apakah kesan urus niaga ini?
C7: A. Aset bertambah RM30 000; ekuiti pemilik bertambah RM30 000
C8: B. Aset bertambah RM30 000; liabiliti bertambah RM30 000
C9: C. Aset berkurang RM30 000; ekuiti pemilik bertambah RM30 000
C10: D. Liabiliti bertambah RM30 000; ekuiti pemilik berkurang RM30 000
B11: Jawapan anda | T11: ="A" -> A
B13: 2. Kedai Nora membayar hutang kepada pembekal dengan cek RM2 400 dan menerima diskaun tunai RM100. Apakah kesan urus niaga ini ke atas aset, liabiliti dan ekuiti pemilik?
C14: A. Aset berkurang RM2 500; liabiliti berkurang RM2 400; ekuiti pemilik berkurang RM100
C15: B. Aset berkurang RM2 400; liabiliti berkurang RM2 500; ekuiti pemilik bertambah RM100
C16: C. Aset bertambah RM2 400; liabiliti berkurang RM2 500; ekuiti pemilik bertambah RM100
C17: D. Aset berkurang RM2 400; liabiliti berkurang RM2 400; tiada kesan ke atas ekuiti pemilik
B18: Jawapan anda | T18: ="B" -> B
B20: 3. Jumlah aset sebuah perniagaan ialah RM85 000 dan jumlah liabilitinya RM23 000. Berapakah ekuiti pemilik?
C21: A. RM23 000
C22: B. RM108 000
C23: C. RM62 000
C24: D. RM85 000
B25: Jawapan anda | T25: ="C" -> C
B27: 4. Modal awal Perniagaan Seri ialah RM40 000. Untung bersih tahun itu RM12 000 dan ambilan RM5 000. Berapakah ekuiti pemilik pada akhir tahun?
C28: A. RM57 000
C29: B. RM52 000
C30: C. RM35 000
C31: D. RM47 000
B32: Jawapan anda | T32: ="D" -> D
B34: 5. Urus niaga manakah yang tidak mengubah jumlah aset?
C35: A. Membeli perabot dengan cek
C36: B. Membayar sewa secara tunai
C37: C. Menerima pinjaman bank
C38: D. Pemilik mengambil tunai untuk kegunaan sendiri
B39: Jawapan anda | T39: ="A" -> A
B41: 6. Barang niaga berkos RM1 500 dijual secara kredit dengan harga RM2 100. Apakah kesan urus niaga ini?
C42: A. Aset bertambah RM2 100; ekuiti pemilik bertambah RM2 100
C43: B. Aset bertambah RM600; ekuiti pemilik bertambah RM600
C44: C. Aset berkurang RM1 500; liabiliti bertambah RM2 100
C45: D. Aset bertambah RM600; liabiliti bertambah RM600
B46: Jawapan anda | T46: ="B" -> B
...
